File: xrd_umap_package_ja/data/cu-75%sn.3000rpm-1-1520-1_1.ras
*RAS_DATA_START
*RAS_HEADER_START
*CORR_POS_DB_NAME "Dtex_20210428"
*CORR_POS_GONIO_RADIUS ""
*CORR_POS_NODE_INDEX01 ""
*CORR_POS_NODE_INDEX02 ""
*CORR_POS_NODE_INDEX03 ""
*CORR_POS_NODE_INDEX04 ""
*CORR_POS_NODE_INDEX05 ""
*CORR_POS_NODE_INDEX06 ""
*CORR_POS_NODE_INDEX07 ""
*CORR_POS_NODE_INDEX08 ""
*CORR_POS_NODE_INDEX09 ""
*CORR_POS_NODE_INDEX10 ""
*CORR_POS_NODE_INDEX11 ""
*CORR_POS_NODE_LABEL01 "Si(111)"
*CORR_POS_NODE_LABEL02 "Si(220)"
*CORR_POS_NODE_LABEL03 "Si(311)"
*CORR_POS_NODE_LABEL04 "Si(400)"
*CORR_POS_NODE_LABEL05 "Si(331)"
*CORR_POS_NODE_LABEL06 "Si(422)"
*CORR_POS_NODE_LABEL07 "Si(511)"
*CORR_POS_NODE_LABEL08 "Si(440)"
*CORR_POS_NODE_LABEL09 "Si(531)"
*CORR_POS_NODE_LABEL10 "Si(620)"
*CORR_POS_NODE_LABEL11 "Si(533)"
*CORR_POS_NODE_POS_CALC01 "28.3773"
*CORR_POS_NODE_POS_CALC02 "47.2511"
*CORR_POS_NODE_POS_CALC03 "56.073"
*CORR_POS_NODE_POS_CALC04 "69.0829"
*CORR_POS_NODE_POS_CALC05 "76.3303"
*CORR_POS_NODE_POS_CALC06 "87.9864"
*CORR_POS_NODE_POS_CALC07 "94.9103"
*CORR_POS_NODE_POS_CALC08 "106.67"
*CORR_POS_NODE_POS_CALC09 "114.056"
*CORR_POS_NODE_POS_CALC10 "127.514"
*CORR_POS_NODE_POS_CALC11 "136.867"
*CORR_POS_NODE_POS_MEAS01 "28.4014"
*CORR_POS_NODE_POS_MEAS02 "47.2553"
*CORR_POS_NODE_POS_MEAS03 "56.0727"
*CORR_POS_NODE_POS_MEAS04 "69.0771"
*CORR_POS_NODE_POS_MEAS05 "76.3223"
*CORR_POS_NODE_POS_MEAS06 "87.9752"
*CORR_POS_NODE_POS_MEAS07 "94.897"
*CORR_POS_NODE_POS_MEAS08 "106.653"
*CORR_POS_NODE_POS_MEAS09 "114.038"
*CORR_POS_NODE_POS_MEAS10 "127.488"
*CORR_POS_NODE_POS_MEAS11 "136.841"
*CORR_POS_OPT_ATTR "集中法"
*CORR_POS_PARAM_MU ""
*CORR_POS_PARAM_PL ""
*CORR_POS_SEMODEL_TYPE "0"
*CORR_POS_STANDARD_TYPE ""
*CORR_POS_VALUE_ANALYZER "None"
*CORR_POS_VALUE_CMONO "None_None"
*CORR_POS_VALUE_IMONO "None"
*CORR_POS_VALUE_IS "1.250deg"
*CORR_POS_VALUE_ISL "10.0mm"
*CORR_POS_VALUE_ISOLLER "5.0deg"
*CORR_POS_VALUE_RS1 "13.0mm"
*CORR_POS_VALUE_RS2 "13.0mm"
*CORR_POS_VALUE_RSOLLER "5.0deg"
*CORR_POS_XG_FOCUS_L ""
*CORR_POS_XG_WAVE_TYPE ""
*CORR_POS_XG_WAVE_VALUE ""
*DISP_FMT_X "%.2f"
*DISP_FMT_Y "%.0f"
*DISP_FULLSCALE "62520.0000000000"
*DISP_LINE_COLOR "255.0000000000"
*DISP_LINE_STYLE "0.0000000000"
*DISP_LINE_WIDTH "0.2500000000"
*DISP_NOTE "測定データ-3"
*DISP_OFFSET_Y "0.0000000000"
*DISP_PEAKSEARCH_UNIT_Y "cps"
*DISP_RANGE_BOTTOM "0.0000000000"
*DISP_RANGE_LEFT "5.0000000000"
*DISP_RANGE_LOGCUTOFF "0.0100000000"
*DISP_RANGE_RIGHT "90.0000000000"
*DISP_RANGE_TOP "62520.0000000000"
*DISP_SCALE_MODE_Y "0.0000000000"
*DISP_TAB_NAME "2θ/θ"
*DISP_TITLE_Y "強度"
*DISP_UNIT_Y "cps"
*DISP_WINDOW_NAME "MSG_MACROENGINE"
*FILE_COMMENT " "
*FILE_MD5 ""
*FILE_MEMO " "
*FILE_OPERATOR "administrator"
*FILE_PART_ID "MEAS_PBEA_00223"
*FILE_SAMPLE "cu-75%sn.3000rpm"
*FILE_TYPE "RAS_RAW"
*FILE_USERGROUP "システムマネージャ"
*FILE_VERSION "1.0000000000"
*HW_ATTACHMENT_ID "ATT1025"
*HW_ATTACHMENT_NAME "標準試料台|Standard Sample Stage"
*HW_COUNTER_ID-0 "CUT0025"
*HW_COUNTER_ID-1 "CUT0020"
*HW_COUNTER_ID-2 "CUT0020"
*HW_COUNTER_ID-3 "CMC0021"
*HW_COUNTER_NAME-0 "D/teX Ultra2|D/teX Ultra2"
*HW_COUNTER_NAME-1 "None|None"
*HW_COUNTER_NAME-2 "None|None"
*HW_COUNTER_NAME-3 "検出器モノクロメータ|Detector monochromator"
*HW_COUNTER_SELECT_NAME "D/teX Ultra2|D/teX Ultra2"
*HW_GONIOMETER_ID "GON0070"
*HW_GONIOMETER_NAME "MiniFlex 300/600|MiniFlex 300/600"
*HW_GONIOMETER_RADIUS-0 "79.0"
*HW_GONIOMETER_RADIUS-1 "91.5"
*HW_GONIOMETER_RADIUS-2 "150.0"
*HW_GONIOMETER_RADIUS-3 "0"
*HW_GONIOMETER_RADIUS-4 "92.7"
*HW_GONIOMETER_RADIUS-5 "139.3"
*HW_GONIOMETER_RADIUS-6 "46.6"
*HW_GONIOMETER_RADIUS-7 "150.0"
*HW_I_OPT_ID-0 "ISL0021"
*HW_I_OPT_ID-1 "ISO0021"
*HW_I_OPT_NAME-0 "発散スリット|Divergence slit"
*HW_I_OPT_NAME-1 "入射平行スリット|Incident parallel slit"
*HW_R_ATTENUATER_AUTOMODE "0"
*HW_R_OPT_ID-0 "RSS0021"
*HW_R_OPT_ID-1 "RSO0021"
*HW_R_OPT_ID-2 "RRS0021"
*HW_R_OPT_NAME-0 "散乱スリット|Scattering slit"
*HW_R_OPT_NAME-1 "受光平行スリット|Receiving soller slit"
*HW_R_OPT_NAME-2 "受光スリット|Receiving slit"
*HW_SAMPLE_HOLDER_ID "SMP0000"
*HW_SAMPLE_HOLDER_NAME "無し|None"
*HW_XG_CURRENT_MAX "15"
*HW_XG_CURRENT_MIN "2"
*HW_XG_CURRENT_RESOLUTION "1"
*HW_XG_CURRENT_UNIT "mA"
*HW_XG_FOCUS "1mm x 10mm"
*HW_XG_FOCUS_TYPE "Normal"
*HW_XG_ID "1060"
*HW_XG_NAME "300W/600W 封入管-B|300W/600W Sealed tube-B"
*HW_XG_TARGET_ATOMIC_NUMBER "29.0000000000"
*HW_XG_TARGET_NAME "Cu"
*HW_XG_TYPE "Hermetic"
*HW_XG_VOLTAGE_MAX "40"
*HW_XG_VOLTAGE_MIN "20"
*HW_XG_VOLTAGE_RESOLUTION "1"
*HW_XG_VOLTAGE_UNIT "kV"
*HW_XG_WATT_MAX "1"
*HW_XG_WATT_UNIT "kW"
*HW_XG_WAVE_LENGTH_ALPHA1 "1.540593"
*HW_XG_WAVE_LENGTH_ALPHA2 "1.544414"
*HW_XG_WAVE_LENGTH_BETA "1.392250"
*MEAS_COND_AXIS_NAME-0 "2θ/θ"
*MEAS_COND_AXIS_NAME-1 "Soller(inc.)"
*MEAS_COND_AXIS_NAME-2 "IHS"
*MEAS_COND_AXIS_NAME-3 "DS"
*MEAS_COND_AXIS_NAME-4 "SS"
*MEAS_COND_AXIS_NAME-5 "Soller(rec.)"
*MEAS_COND_AXIS_NAME-6 "RS"
*MEAS_COND_AXIS_NAME-7 "フィルター"
*MEAS_COND_AXIS_NAME-8 "モノクロメータ"
*MEAS_COND_AXIS_NAME-9 "PHA"
*MEAS_COND_AXIS_NAME_INTERNAL-0 "TwoThetaTheta"
*MEAS_COND_AXIS_NAME_INTERNAL-1 "IncidentSollerSlit"
*MEAS_COND_AXIS_NAME_INTERNAL-2 "IncidentAxdSlit"
*MEAS_COND_AXIS_NAME_INTERNAL-3 "IncidentSlitBox"
*MEAS_COND_AXIS_NAME_INTERNAL-4 "ReceivingSlitBox1"
*MEAS_COND_AXIS_NAME_INTERNAL-5 "ReceivingSollerSlit"
*MEAS_COND_AXIS_NAME_INTERNAL-6 "ReceivingSlitBox2"
*MEAS_COND_AXIS_NAME_INTERNAL-7 "Filter"
*MEAS_COND_AXIS_NAME_INTERNAL-8 "CounterMonochromator"
*MEAS_COND_AXIS_NAME_INTERNAL-9 "PHA"
*MEAS_COND_AXIS_NAME_MAGICNO-0 "268632064.0000000000"
*MEAS_COND_AXIS_NAME_MAGICNO-1 "20971521.0000000000"
*MEAS_COND_AXIS_NAME_MAGICNO-2 "22020097.0000000000"
*MEAS_COND_AXIS_NAME_MAGICNO-3 "22020097.0000000000"
*MEAS_COND_AXIS_NAME_MAGICNO-4 "23068673.0000000000"
*MEAS_COND_AXIS_NAME_MAGICNO-5 "20971521.0000000000"
*MEAS_COND_AXIS_NAME_MAGICNO-6 "23068673.0000000000"
*MEAS_COND_AXIS_NAME_MAGICNO-7 "20971521.0000000000"
*MEAS_COND_AXIS_NAME_MAGICNO-8 "20971521.0000000000"
*MEAS_COND_AXIS_NAME_MAGICNO-9 "0.0000000000"
*MEAS_COND_AXIS_OFFSET-0 "0.0000000000"
*MEAS_COND_AXIS_OFFSET-1 "-"
*MEAS_COND_AXIS_OFFSET-2 "-"
*MEAS_COND_AXIS_OFFSET-3 "-"
*MEAS_COND_AXIS_OFFSET-4 "-"
*MEAS_COND_AXIS_OFFSET-5 "-"
*MEAS_COND_AXIS_OFFSET-6 "-"
*MEAS_COND_AXIS_OFFSET-7 "-"
*MEAS_COND_AXIS_OFFSET-8 "-"
*MEAS_COND_AXIS_OFFSET-9 "-"
*MEAS_COND_AXIS_POSITION-0 "12.0000000000"
*MEAS_COND_AXIS_POSITION-1 "5.0deg"
*MEAS_COND_AXIS_POSITION-2 "10.0mm"
*MEAS_COND_AXIS_POSITION-3 "1.250deg"
*MEAS_COND_AXIS_POSITION-4 "8.0mm"
*MEAS_COND_AXIS_POSITION-5 "5.0deg"
*MEAS_COND_AXIS_POSITION-6 "13.0mm(Open)"
*MEAS_COND_AXIS_POSITION-7 "K-beta(x2)"
*MEAS_COND_AXIS_POSITION-8 "None"
*MEAS_COND_AXIS_POSITION-9 "48.0000000000"
*MEAS_COND_AXIS_UNIT-0 "deg"
*MEAS_COND_AXIS_UNIT-1 ""
*MEAS_COND_AXIS_UNIT-2 ""
*MEAS_COND_AXIS_UNIT-3 ""
*MEAS_COND_AXIS_UNIT-4 ""
*MEAS_COND_AXIS_UNIT-5 ""
*MEAS_COND_AXIS_UNIT-6 ""
*MEAS_COND_AXIS_UNIT-7 ""
*MEAS_COND_AXIS_UNIT-8 ""
*MEAS_COND_AXIS_UNIT-9 "div"
*MEAS_COND_COUNTER_CNTLOSS_CORR "0.0000000000"
*MEAS_COND_COUNTER_PHABASE "48.0000000000"
*MEAS_COND_COUNTER_PHAWINDOW "9.0000000000"
*MEAS_COND_COUNTER_PHA_UNIT "div"
*MEAS_COND_COUNTER_TAUDIFF "0.2500000000"
*MEAS_COND_COUNTER_TAUINT "0.7500000000"
*MEAS_COND_IRRADIATION_MODE "OFF"
*MEAS_COND_IRRADIATION_WIDTH ""
*MEAS_COND_OPT_ATTR " "
*MEAS_COND_OPT_NAME ""
*MEAS_COND_UNSYMMETRIC_MODE "OFF"
*MEAS_COND_XG_CURRENT "15.0000000000"
*MEAS_COND_XG_VOLTAGE "40.0000000000"
*MEAS_COND_XG_WAVE_TYPE "Ka"
*MEAS_DATA_COUNT "8501.0000000000"
*MEAS_SCAN_AXIS_X "2θ/θ"
*MEAS_SCAN_AXIS_X_INTERNAL "TwoThetaTheta"
*MEAS_SCAN_END_TIME "04/09/24 15:26:17"
*MEAS_SCAN_MODE "CONTINUOUS"
*MEAS_SCAN_MONITOR "0"
*MEAS_SCAN_RESOLUTION_X "0.0025"
*MEAS_SCAN_SPEED "20.000000"
*MEAS_SCAN_SPEED_UNIT "deg/min"
*MEAS_SCAN_SPEED_USER "20.000000"
*MEAS_SCAN_START "5.0000000000"
*MEAS_SCAN_START_TIME "04/09/24 15:21:30"
*MEAS_SCAN_STEP "0.0100000000"
*MEAS_SCAN_STOP "90.0000000000"
*MEAS_SCAN_UNIT_X "deg"
*MEAS_SCAN_UNIT_Y "counts"
*SLIT_SYSTEM "0"
*RAS_HEADER_END
*RAS_INT_START
5.0000 229.0000 1.0000
5.0600 218.0000 1.0000
5.1200 208.0000 1.0000
5.1800 227.0000 1.0000
5.2400 217.0000 1.0000
5.3000 226.0000 1.0000
5.3600 209.0000 1.0000
5.4200 222.0000 1.0000
5.4800 225.0000 1.0000
5.5400 210.0000 1.0000
5.6000 218.0000 1.0000
5.6600 227.0000 1.0000
5.7200 223.0000 1.0000
5.7800 225.0000 1.0000
5.8400 253.0000 1.0000
5.9000 245.0000 1.0000
5.9600 233.0000 1.0000
6.0200 231.0000 1.0000
6.0800 218.0000 1.0000
6.1400 216.0000 1.0000
6.2000 225.0000 1.0000
6.2600 222.0000 1.0000
6.3200 222.0000 1.0000
6.3800 219.0000 1.0000
6.4400 238.0000 1.0000
6.5000 239.0000 1.0000
6.5600 223.0000 1.0000
6.6200 232.0000 1.0000
6.6800 223.0000 1.0000
6.7400 233.0000 1.0000
6.8000 225.0000 1.0000
6.8600 215.0000 1.0000
6.9200 235.0000 1.0000
6.9800 204.0000 1.0000
7.0400 232.0000 1.0000
7.1000 225.0000 1.0000
7.1600 224.0000 1.0000
7.2200 226.0000 1.0000
7.2800 246.0000 1.0000
7.3400 220.0000 1.0000
7.4000 249.0000 1.0000
7.4600 244.0000 1.0000
7.5200 221.0000 1.0000
7.5800 252.0000 1.0000
7.6400 238.0000 1.0000
7.7000 246.0000 1.0000
7.7600 234.0000 1.0000
7.8200 248.0000 1.0000
7.8800 224.0000 1.0000
7.9400 223.0000 1.0000
8.0000 248.0000 1.0000
8.0600 256.0000 1.0000
8.1200 235.0000 1.0000
8.1800 254.0000 1.0000
8.2400 250.0000 1.0000
8.3000 237.0000 1.0000
8.3600 262.0000 1.0000
8.4200 245.0000 1.0000
8.4800 245.0000 1.0000
8.5400 250.0000 1.0000
8.6000 237.0000 1.0000
8.6600 250.0000 1.0000
8.7200 241.0000 1.0000
8.7800 266.0000 1.0000
8.8400 252.0000 1.0000
8.9000 252.0000 1.0000
8.9600 265.0000 1.0000
9.0200 259.0000 1.0000
9.0800 262.0000 1.0000
9.1400 268.0000 1.0000
9.2000 265.0000 1.0000
9.2600 268.0000 1.0000
9.3200 249.0000 1.0000
9.3800 262.0000 1.0000
9.4400 264.0000 1.0000
9.5000 259.0000 1.0000
9.5600 257.0000 1.0000
9.6200 250.0000 1.0000
9.6800 263.0000 1.0000
9.7400 277.0000 1.0000
9.8000 274.0000 1.0000
9.8600 275.0000 1.0000
9.9200 270.0000 1.0000
9.9800 265.0000 1.0000
10.0400 276.0000 1.0000
10.1000 261.0000 1.0000
10.1600 263.0000 1.0000
10.2200 255.0000 1.0000
10.2800 264.0000 1.0000
10.3400 278.0000 1.0000
10.4000 285.0000 1.0000
10.4600 267.0000 1.0000
10.5200 273.0000 1.0000
10.5800 295.0000 1.0000
10.6400 275.0000 1.0000
10.7000 265.0000 1.0000
10.7600 281.0000 1.0000
10.8200 276.0000 1.0000
10.8800 281.0000 1.0000
10.9400 269.0000 1.0000
11.0000 277.0000 1.0000
11.0600 282.0000 1.0000
11.1200 285.0000 1.0000
11.1800 278.0000 1.0000
11.2400 294.0000 1.0000
11.3000 278.0000 1.0000
11.3600 299.0000 1.0000
11.4200 281.0000 1.0000
11.4800 303.0000 1.0000
11.5400 283.0000 1.0000
11.6000 280.0000 1.0000
11.6600 287.0000 1.0000
11.7200 294.0000 1.0000
11.7800 270.0000 1.0000
11.8400 264.0000 1.0000
11.9000 296.0000 1.0000
11.9600 298.0000 1.0000
12.0200 306.0000 1.0000
12.0800 290.0000 1.0000
12.1400 291.0000 1.0000
12.2000 275.0000 1.0000
12.2600 283.0000 1.0000
12.3200 285.0000 1.0000
12.3800 298.0000 1.0000
12.4400 271.0000 1.0000
12.5000 277.0000 1.0000
12.5600 295.0000 1.0000
12.6200 317.0000 1.0000
12.6800 295.0000 1.0000
12.7400 311.0000 1.0000
12.8000 310.0000 1.0000
12.8600 312.0000 1.0000
12.9200 292.0000 1.0000
12.9800 304.0000 1.0000
13.0400 286.0000 1.0000
13.1000 276.0000 1.0000
13.1600 319.0000 1.0000
13.2200 319.0000 1.0000
13.2800 326.0000 1.0000
13.3400 309.0000 1.0000
13.4000 306.0000 1.0000
13.4600 291.0000 1.0000
13.5200 306.0000 1.0000
13.5800 296.0000 1.0000
13.6400 296.0000 1.0000
13.7000 303.0000 1.0000
13.7600 304.0000 1.0000
13.8200 273.0000 1.0000
13.8800 295.0000 1.0000
13.9400 304.0000 1.0000
14.0000 290.0000 1.0000
14.0600 300.0000 1.0000
14.1200 292.0000 1.0000
14.1800 297.0000 1.0000
14.2400 316.0000 1.0000
14.3000 285.0000 1.0000
14.3600 290.0000 1.0000
14.4200 289.0000 1.0000
14.4800 270.0000 1.0000
14.5400 262.0000 1.0000
14.6000 266.0000 1.0000
14.6600 266.0000 1.0000
14.7200 286.0000 1.0000
14.7800 292.0000 1.0000
14.8400 261.0000 1.0000
14.9000 298.0000 1.0000
14.9600 271.0000 1.0000
15.0200 290.0000 1.0000
15.0800 281.0000 1.0000
15.1400 279.0000 1.0000
15.2000 271.0000 1.0000
15.2600 277.0000 1.0000
15.3200 292.0000 1.0000
15.3800 295.0000 1.0000
15.4400 293.0000 1.0000
15.5000 274.0000 1.0000
15.5600 298.0000 1.0000
15.6200 268.0000 1.0000
15.6800 285.0000 1.0000
15.7400 255.0000 1.0000
15.8000 307.0000 1.0000
15.8600 280.0000 1.0000
15.9200 287.0000 1.0000
15.9800 287.0000 1.0000
16.0400 266.0000 1.0000
16.1000 268.0000 1.0000
16.1600 280.0000 1.0000
16.2200 270.0000 1.0000
16.2800 287.0000 1.0000
16.3400 278.0000 1.0000
16.4000 280.0000 1.0000
16.4600 273.0000 1.0000
16.5200 272.0000 1.0000
16.5800 279.0000 1.0000
16.6400 276.0000 1.0000
16.7000 279.0000 1.0000
16.7600 285.0000 1.0000
16.8200 255.0000 1.0000
16.8800 273.0000 1.0000
16.9400 275.0000 1.0000
17.0000 267.0000 1.0000
17.0600 262.0000 1.0000
17.1200 269.0000 1.0000
17.1800 247.0000 1.0000
17.2400 283.0000 1.0000
17.3000 264.0000 1.0000
17.3600 254.0000 1.0000
17.4200 253.0000 1.0000
17.4800 282.0000 1.0000
17.5400 258.0000 1.0000
17.6000 254.0000 1.0000
17.6600 250.0000 1.0000
17.7200 265.0000 1.0000
17.7800 242.0000 1.0000
17.8400 262.0000 1.0000
17.9000 246.0000 1.0000
17.9600 243.0000 1.0000
18.0200 266.0000 1.0000
18.0800 247.0000 1.0000
18.1400 255.0000 1.0000
18.2000 265.0000 1.0000
18.2600 268.0000 1.0000
18.3200 255.0000 1.0000
18.3800 257.0000 1.0000
18.4400 248.0000 1.0000
18.5000 258.0000 1.0000
18.5600 264.0000 1.0000
18.6200 251.0000 1.0000
18.6800 260.0000 1.0000
18.7400 246.0000 1.0000
18.8000 245.0000 1.0000
18.8600 257.0000 1.0000
18.9200 252.0000 1.0000
18.9800 239.0000 1.0000
19.0400 253.0000 1.0000
19.1000 230.0000 1.0000
19.1600 258.0000 1.0000
19.2200 243.0000 1.0000
19.2800 259.0000 1.0000
19.3400 241.0000 1.0000
19.4000 234.0000 1.0000
19.4600 247.0000 1.0000
19.5200 219.0000 1.0000
19.5800 225.0000 1.0000
19.6400 248.0000 1.0000
19.7000 236.0000 1.0000
19.7600 258.0000 1.0000
19.8200 222.0000 1.0000
19.8800 238.0000 1.0000
19.9400 218.0000 1.0000
20.0000 232.0000 1.0000
20.0600 228.0000 1.0000
20.1200 233.0000 1.0000
20.1800 219.0000 1.0000
20.2400 235.0000 1.0000
20.3000 200.0000 1.0000
20.3600 240.0000 1.0000
20.4200 226.0000 1.0000
20.4800 214.0000 1.0000
20.5400 223.0000 1.0000
20.6000 235.0000 1.0000
20.6600 234.0000 1.0000
20.7200 227.0000 1.0000
20.7800 223.0000 1.0000
20.8400 214.0000 1.0000
20.9000 200.0000 1.0000
20.9600 207.0000 1.0000
21.0200 215.0000 1.0000
21.0800 199.0000 1.0000
21.1400 218.0000 1.0000
21.2000 211.0000 1.0000
21.2600 218.0000 1.0000
21.3200 205.0000 1.0000
21.3800 215.0000 1.0000
21.4400 219.0000 1.0000
21.5000 194.0000 1.0000
21.5600 201.0000 1.0000
21.6200 210.0000 1.0000
21.6800 201.0000 1.0000
21.7400 189.0000 1.0000
21.8000 207.0000 1.0000
21.8600 186.0000 1.0000
21.9200 206.0000 1.0000
21.9800 194.0000 1.0000
22.0400 204.0000 1.0000
22.1000 192.0000 1.0000
22.1600 181.0000 1.0000
22.2200 183.0000 1.0000
22.2800 175.0000 1.0000
22.3400 179.0000 1.0000
22.4000 197.0000 1.0000
22.4600 190.0000 1.0000
22.5200 200.0000 1.0000
22.5800 194.0000 1.0000
22.6400 207.0000 1.0000
22.7000 191.0000 1.0000
22.7600 174.0000 1.0000
22.8200 183.0000 1.0000
22.8800 181.0000 1.0000
22.9400 184.0000 1.0000
23.0000 169.0000 1.0000
23.0600 190.0000 1.0000
23.1200 193.0000 1.0000
23.1800 172.0000 1.0000
23.2400 173.0000 1.0000
23.3000 200.0000 1.0000
23.3600 174.0000 1.0000
23.4200 167.0000 1.0000
23.4800 179.0000 1.0000
23.5400 197.0000 1.0000
23.6000 197.0000 1.0000
23.6600 174.0000 1.0000
23.7200 177.0000 1.0000
23.7800 170.0000 1.0000
23.8400 150.0000 1.0000
23.9000 163.0000 1.0000
23.9600 176.0000 1.0000
24.0200 163.0000 1.0000
24.0800 167.0000 1.0000
24.1400 179.0000 1.0000
24.2000 165.0000 1.0000
24.2600 184.0000 1.0000
24.3200 178.0000 1.0000
24.3800 151.0000 1.0000
24.4400 152.0000 1.0000
24.5000 164.0000 1.0000
24.5600 157.0000 1.0000
24.6200 176.0000 1.0000
24.6800 169.0000 1.0000
24.7400 164.0000 1.0000
24.8000 173.0000 1.0000
24.8600 163.0000 1.0000
24.9200 158.0000 1.0000
24.9800 168.0000 1.0000
25.0400 167.0000 1.0000
25.1000 145.0000 1.0000
25.1600 150.0000 1.0000
25.2200 157.0000 1.0000
25.2800 157.0000 1.0000
25.3400 154.0000 1.0000
25.4000 158.0000 1.0000
25.4600 168.0000 1.0000
25.5200 162.0000 1.0000
25.5800 160.0000 1.0000
25.6400 151.0000 1.0000
25.7000 142.0000 1.0000
25.7600 146.0000 1.0000
25.8200 151.0000 1.0000
25.8800 147.0000 1.0000
25.9400 146.0000 1.0000
26.0000 149.0000 1.0000
26.0600 150.0000 1.0000
26.1200 137.0000 1.0000
26.1800 156.0000 1.0000
26.2400 150.0000 1.0000
26.3000 148.0000 1.0000
26.3600 148.0000 1.0000
26.4200 139.0000 1.0000
26.4800 146.0000 1.0000
26.5400 135.0000 1.0000
26.6000 143.0000 1.0000
26.6600 142.0000 1.0000
26.7200 139.0000 1.0000
26.7800 144.0000 1.0000
26.8400 129.0000 1.0000
26.9000 121.0000 1.0000
26.9600 147.0000 1.0000
27.0200 124.0000 1.0000
27.0800 146.0000 1.0000
27.1400 144.0000 1.0000
27.2000 137.0000 1.0000
27.2600 139.0000 1.0000
27.3200 123.0000 1.0000
27.3800 120.0000 1.0000
27.4400 133.0000 1.0000
27.5000 142.0000 1.0000
27.5600 139.0000 1.0000
27.6200 126.0000 1.0000
27.6800 134.0000 1.0000
27.7400 129.0000 1.0000
27.8000 132.0000 1.0000
27.8600 132.0000 1.0000
27.9200 137.0000 1.0000
27.9800 137.0000 1.0000
28.0400 132.0000 1.0000
28.1000 138.0000 1.0000
28.1600 136.0000 1.0000
28.2200 132.0000 1.0000
28.2800 127.0000 1.0000
28.3400 129.0000 1.0000
28.4000 120.0000 1.0000
28.4600 122.0000 1.0000
28.5200 136.0000 1.0000
28.5800 127.0000 1.0000
28.6400 130.0000 1.0000
28.7000 135.0000 1.0000
28.7600 131.0000 1.0000
28.8200 133.0000 1.0000
28.8800 128.0000 1.0000
28.9400 123.0000 1.0000
29.0000 125.0000 1.0000
29.0600 109.0000 1.0000
29.1200 124.0000 1.0000
29.1800 119.0000 1.0000
29.2400 119.0000 1.0000
29.3000 126.0000 1.0000
29.3600 125.0000 1.0000
29.4200 122.0000 1.0000
29.4800 124.0000 1.0000
29.5400 128.0000 1.0000
29.6000 123.0000 1.0000
29.6600 139.0000 1.0000
29.7200 133.0000 1.0000
29.7800 149.0000 1.0000
29.8400 156.0000 1.0000
29.9000 176.0000 1.0000
29.9600 229.0000 1.0000
30.0200 295.0000 1.0000
30.0800 325.0000 1.0000
30.1400 286.0000 1.0000
30.2000 242.0000 1.0000
30.2600 222.0000 1.0000
30.3200 239.0000 1.0000
30.3800 345.0000 1.0000
30.4400 632.0000 1.0000
30.5000 1237.0000 1.0000
30.5600 1488.0000 1.0000
30.6200 1043.0000 1.0000
30.6800 482.0000 1.0000
30.7400 242.0000 1.0000
30.8000 217.0000 1.0000
30.8600 172.0000 1.0000
30.9200 135.0000 1.0000
30.9800 135.0000 1.0000
31.0400 129.0000 1.0000
31.1000 119.0000 1.0000
31.1600 138.0000 1.0000
31.2200 112.0000 1.0000
31.2800 131.0000 1.0000
31.3400 132.0000 1.0000
31.4000 127.0000 1.0000
31.4600 129.0000 1.0000
31.5200 140.0000 1.0000
31.5800 136.0000 1.0000
31.6400 141.0000 1.0000
31.7000 148.0000 1.0000
31.7600 190.0000 1.0000
31.8200 287.0000 1.0000
31.8800 704.0000 1.0000
31.9400 868.0000 1.0000
32.0000 557.0000 1.0000
32.0600 261.0000 1.0000
32.1200 159.0000 1.0000
32.1800 136.0000 1.0000
32.2400 149.0000 1.0000
32.3000 114.0000 1.0000
32.3600 110.0000 1.0000
32.4200 109.0000 1.0000
32.4800 109.0000 1.0000
32.5400 104.0000 1.0000
32.6000 103.0000 1.0000
32.6600 120.0000 1.0000
32.7200 108.0000 1.0000
32.7800 117.0000 1.0000
32.8400 113.0000 1.0000
32.9000 103.0000 1.0000
32.9600 112.0000 1.0000
33.0200 112.0000 1.0000
33.0800 107.0000 1.0000
33.1400 93.0000 1.0000
33.2000 97.0000 1.0000
33.2600 100.0000 1.0000
33.3200 115.0000 1.0000
33.3800 98.0000 1.0000
33.4400 89.0000 1.0000
33.5000 104.0000 1.0000
33.5600 105.0000 1.0000
33.6200 117.0000 1.0000
33.6800 93.0000 1.0000
33.7400 98.0000 1.0000
33.8000 87.0000 1.0000
33.8600 106.0000 1.0000
33.9200 97.0000 1.0000
33.9800 109.0000 1.0000
34.0400 97.0000 1.0000
34.1000 98.0000 1.0000
34.1600 97.0000 1.0000
34.2200 85.0000 1.0000
34.2800 95.0000 1.0000
34.3400 95.0000 1.0000
34.4000 93.0000 1.0000
34.4600 102.0000 1.0000
34.5200 97.0000 1.0000
34.5800 100.0000 1.0000
34.6400 96.0000 1.0000
34.7000 90.0000 1.0000
34.7600 90.0000 1.0000
34.8200 93.0000 1.0000
34.8800 97.0000 1.0000
34.9400 99.0000 1.0000
35.0000 87.0000 1.0000
35.0600 93.0000 1.0000
35.1200 85.0000 1.0000
35.1800 86.0000 1.0000
35.2400 100.0000 1.0000
35.3000 94.0000 1.0000
35.3600 87.0000 1.0000
35.4200 93.0000 1.0000
35.4800 106.0000 1.0000
35.5400 84.0000 1.0000
35.6000 83.0000 1.0000
35.6600 101.0000 1.0000
35.7200 78.0000 1.0000
35.7800 92.0000 1.0000
35.8400 89.0000 1.0000
35.9000 83.0000 1.0000
35.9600 97.0000 1.0000
36.0200 93.0000 1.0000
36.0800 95.0000 1.0000
36.1400 80.0000 1.0000
36.2000 85.0000 1.0000
36.2600 82.0000 1.0000
36.3200 89.0000 1.0000
36.3800 88.0000 1.0000
36.4400 91.0000 1.0000
36.5000 83.0000 1.0000
36.5600 89.0000 1.0000
36.6200 82.0000 1.0000
36.6800 93.0000 1.0000
36.7400 80.0000 1.0000
36.8000 85.0000 1.0000
36.8600 88.0000 1.0000
36.9200 77.0000 1.0000
36.9800 83.0000 1.0000
37.0400 79.0000 1.0000
37.1000 75.0000 1.0000
37.1600 82.0000 1.0000
37.2200 75.0000 1.0000
37.2800 74.0000 1.0000
37.3400 74.0000 1.0000
37.4000 79.0000 1.0000
37.4600 80.0000 1.0000
37.5200 85.0000 1.0000
37.5800 73.0000 1.0000
37.6400 82.0000 1.0000
37.7000 84.0000 1.0000
37.7600 90.0000 1.0000
37.8200 90.0000 1.0000
37.8800 76.0000 1.0000
37.9400 74.0000 1.0000
38.0000 69.0000 1.0000
38.0600 94.0000 1.0000
38.1200 80.0000 1.0000
38.1800 84.0000 1.0000
38.2400 75.0000 1.0000
38.3000 73.0000 1.0000
38.3600 76.0000 1.0000
38.4200 76.0000 1.0000
38.4800 79.0000 1.0000
38.5400 92.0000 1.0000
38.6000 86.0000 1.0000
38.6600 68.0000 1.0000
38.7200 86.0000 1.0000
38.7800 87.0000 1.0000
38.8400 70.0000 1.0000
38.9000 79.0000 1.0000
38.9600 78.0000 1.0000
39.0200 78.0000 1.0000
39.0800 81.0000 1.0000
39.1400 83.0000 1.0000
39.2000 67.0000 1.0000
39.2600 81.0000 1.0000
39.3200 80.0000 1.0000
39.3800 74.0000 1.0000
39.4400 81.0000 1.0000
39.5000 83.0000 1.0000
39.5600 78.0000 1.0000
39.6200 76.0000 1.0000
39.6800 79.0000 1.0000
39.7400 75.0000 1.0000
39.8000 67.0000 1.0000
39.8600 75.0000 1.0000
39.9200 73.0000 1.0000
39.9800 88.0000 1.0000
40.0400 79.0000 1.0000
40.1000 71.0000 1.0000
40.1600 74.0000 1.0000
40.2200 70.0000 1.0000
40.2800 87.0000 1.0000
40.3400 72.0000 1.0000
40.4000 68.0000 1.0000
40.4600 75.0000 1.0000
40.5200 73.0000 1.0000
40.5800 73.0000 1.0000
40.6400 77.0000 1.0000
40.7000 63.0000 1.0000
40.7600 69.0000 1.0000
40.8200 74.0000 1.0000
40.8800 85.0000 1.0000
40.9400 74.0000 1.0000
41.0000 70.0000 1.0000
41.0600 73.0000 1.0000
41.1200 68.0000 1.0000
41.1800 74.0000 1.0000
41.2400 68.0000 1.0000
41.3000 71.0000 1.0000
41.3600 63.0000 1.0000
41.4200 85.0000 1.0000
41.4800 66.0000 1.0000
41.5400 83.0000 1.0000
41.6000 86.0000 1.0000
41.6600 81.0000 1.0000
41.7200 68.0000 1.0000
41.7800 72.0000 1.0000
41.8400 69.0000 1.0000
41.9000 79.0000 1.0000
41.9600 64.0000 1.0000
42.0200 81.0000 1.0000
42.0800 87.0000 1.0000
42.1400 74.0000 1.0000
42.2000 65.0000 1.0000
42.2600 76.0000 1.0000
42.3200 79.0000 1.0000
42.3800 71.0000 1.0000
42.4400 76.0000 1.0000
42.5000 91.0000 1.0000
42.5600 79.0000 1.0000
42.6200 93.0000 1.0000
42.6800 117.0000 1.0000
42.7400 142.0000 1.0000
42.8000 172.0000 1.0000
42.8600 214.0000 1.0000
42.9200 269.0000 1.0000
42.9800 242.0000 1.0000
43.0400 198.0000 1.0000
43.1000 174.0000 1.0000
43.1600 185.0000 1.0000
43.2200 189.0000 1.0000
43.2800 177.0000 1.0000
43.3400 163.0000 1.0000
43.4000 122.0000 1.0000
43.4600 110.0000 1.0000
43.5200 98.0000 1.0000
43.5800 83.0000 1.0000
43.6400 103.0000 1.0000
43.7000 119.0000 1.0000
43.7600 203.0000 1.0000
43.8200 214.0000 1.0000
43.8800 167.0000 1.0000
43.9400 136.0000 1.0000
44.0000 99.0000 1.0000
44.0600 74.0000 1.0000
44.1200 77.0000 1.0000
44.1800 75.0000 1.0000
44.2400 68.0000 1.0000
44.3000 78.0000 1.0000
44.3600 80.0000 1.0000
44.4200 83.0000 1.0000
44.4800 97.0000 1.0000
44.5400 88.0000 1.0000
44.6000 114.0000 1.0000
44.6600 115.0000 1.0000
44.7200 189.0000 1.0000
44.7800 377.0000 1.0000
44.8400 453.0000 1.0000
44.9000 306.0000 1.0000
44.9600 255.0000 1.0000
45.0200 137.0000 1.0000
45.0800 95.0000 1.0000
45.1400 79.0000 1.0000
45.2000 79.0000 1.0000
45.2600 75.0000 1.0000
45.3200 75.0000 1.0000
45.3800 69.0000 1.0000
45.4400 69.0000 1.0000
45.5000 75.0000 1.0000
45.5600 73.0000 1.0000
45.6200 68.0000 1.0000
45.6800 67.0000 1.0000
45.7400 76.0000 1.0000
45.8000 71.0000 1.0000
45.8600 71.0000 1.0000
45.9200 65.0000 1.0000
45.9800 71.0000 1.0000
46.0400 68.0000 1.0000
46.1000 68.0000 1.0000
46.1600 67.0000 1.0000
46.2200 64.0000 1.0000
46.2800 72.0000 1.0000
46.3400 71.0000 1.0000
46.4000 72.0000 1.0000
46.4600 71.0000 1.0000
46.5200 57.0000 1.0000
46.5800 75.0000 1.0000
46.6400 70.0000 1.0000
46.7000 64.0000 1.0000
46.7600 66.0000 1.0000
46.8200 70.0000 1.0000
46.8800 60.0000 1.0000
46.9400 68.0000 1.0000
47.0000 75.0000 1.0000
47.0600 61.0000 1.0000
47.1200 69.0000 1.0000
47.1800 68.0000 1.0000
47.2400 75.0000 1.0000
47.3000 60.0000 1.0000
47.3600 72.0000 1.0000
47.4200 67.0000 1.0000
47.4800 57.0000 1.0000
47.5400 73.0000 1.0000
47.6000 69.0000 1.0000
47.6600 64.0000 1.0000
47.7200 65.0000 1.0000
47.7800 68.0000 1.0000
47.8400 55.0000 1.0000
47.9000 61.0000 1.0000
47.9600 70.0000 1.0000
48.0200 71.0000 1.0000
48.0800 68.0000 1.0000
48.1400 69.0000 1.0000
48.2000 69.0000 1.0000
48.2600 65.0000 1.0000
48.3200 66.0000 1.0000
48.3800 66.0000 1.0000
48.4400 79.0000 1.0000
48.5000 62.0000 1.0000
48.5600 58.0000 1.0000
48.6200 63.0000 1.0000
48.6800 64.0000 1.0000
48.7400 66.0000 1.0000
48.8000 73.0000 1.0000
48.8600 71.0000 1.0000
48.9200 64.0000 1.0000
48.9800 64.0000 1.0000
49.0400 68.0000 1.0000
49.1000 60.0000 1.0000
49.1600 68.0000 1.0000
49.2200 69.0000 1.0000
49.2800 60.0000 1.0000
49.3400 73.0000 1.0000
49.4000 61.0000 1.0000
49.4600 65.0000 1.0000
49.5200 67.0000 1.0000
49.5800 64.0000 1.0000
49.6400 56.0000 1.0000
49.7000 64.0000 1.0000
49.7600 53.0000 1.0000
49.8200 59.0000 1.0000
49.8800 56.0000 1.0000
49.9400 65.0000 1.0000
50.0000 68.0000 1.0000
50.0600 60.0000 1.0000
50.1200 67.0000 1.0000
50.1800 55.0000 1.0000
50.2400 57.0000 1.0000
50.3000 54.0000 1.0000
50.3600 70.0000 1.0000
50.4200 64.0000 1.0000
50.4800 56.0000 1.0000
50.5400 60.0000 1.0000
50.6000 60.0000 1.0000
50.6600 53.0000 1.0000
50.7200 64.0000 1.0000
50.7800 68.0000 1.0000
50.8400 70.0000 1.0000
50.9000 60.0000 1.0000
50.9600 60.0000 1.0000
51.0200 59.0000 1.0000
51.0800 56.0000 1.0000
51.1400 54.0000 1.0000
51.2000 60.0000 1.0000
51.2600 71.0000 1.0000
51.3200 59.0000 1.0000
51.3800 69.0000 1.0000
51.4400 61.0000 1.0000
51.5000 63.0000 1.0000
51.5600 61.0000 1.0000
51.6200 65.0000 1.0000
51.6800 61.0000 1.0000
51.7400 59.0000 1.0000
51.8000 65.0000 1.0000
51.8600 62.0000 1.0000
51.9200 62.0000 1.0000
51.9800 62.0000 1.0000
52.0400 60.0000 1.0000
52.1000 65.0000 1.0000
52.1600 66.0000 1.0000
52.2200 67.0000 1.0000
52.2800 70.0000 1.0000
52.3400 57.0000 1.0000
52.4000 63.0000 1.0000
52.4600 59.0000 1.0000
52.5200 67.0000 1.0000
52.5800 64.0000 1.0000
52.6400 60.0000 1.0000
52.7000 67.0000 1.0000
52.7600 66.0000 1.0000
52.8200 61.0000 1.0000
52.8800 69.0000 1.0000
52.9400 75.0000 1.0000
53.0000 70.0000 1.0000
53.0600 75.0000 1.0000
53.1200 85.0000 1.0000
53.1800 80.0000 1.0000
53.2400 88.0000 1.0000
53.3000 98.0000 1.0000
53.3600 96.0000 1.0000
53.4200 100.0000 1.0000
53.4800 91.0000 1.0000
53.5400 67.0000 1.0000
53.6000 79.0000 1.0000
53.6600 79.0000 1.0000
53.7200 56.0000 1.0000
53.7800 65.0000 1.0000
53.8400 63.0000 1.0000
53.9000 63.0000 1.0000
53.9600 63.0000 1.0000
54.0200 62.0000 1.0000
54.0800 71.0000 1.0000
54.1400 62.0000 1.0000
54.2000 71.0000 1.0000
54.2600 75.0000 1.0000
54.3200 71.0000 1.0000
54.3800 57.0000 1.0000
54.4400 68.0000 1.0000
54.5000 70.0000 1.0000
54.5600 60.0000 1.0000
54.6200 73.0000 1.0000
54.6800 58.0000 1.0000
54.7400 69.0000 1.0000
54.8000 72.0000 1.0000
54.8600 67.0000 1.0000
54.9200 71.0000 1.0000
54.9800 71.0000 1.0000
55.0400 76.0000 1.0000
55.1000 79.0000 1.0000
55.1600 101.0000 1.0000
55.2200 163.0000 1.0000
55.2800 142.0000 1.0000
55.3400 121.0000 1.0000
55.4000 131.0000 1.0000
55.4600 92.0000 1.0000
55.5200 86.0000 1.0000
55.5800 80.0000 1.0000
55.6400 72.0000 1.0000
55.7000 76.0000 1.0000
55.7600 70.0000 1.0000
55.8200 60.0000 1.0000
55.8800 61.0000 1.0000
55.9400 66.0000 1.0000
56.0000 54.0000 1.0000
56.0600 76.0000 1.0000
56.1200 66.0000 1.0000
56.1800 66.0000 1.0000
56.2400 68.0000 1.0000
56.3000 64.0000 1.0000
56.3600 67.0000 1.0000
56.4200 82.0000 1.0000
56.4800 74.0000 1.0000
56.5400 70.0000 1.0000
56.6000 88.0000 1.0000
56.6600 84.0000 1.0000
56.7200 79.0000 1.0000
56.7800 78.0000 1.0000
56.8400 75.0000 1.0000
56.9000 65.0000 1.0000
56.9600 69.0000 1.0000
57.0200 73.0000 1.0000
57.0800 59.0000 1.0000
57.1400 76.0000 1.0000
57.2000 65.0000 1.0000
57.2600 64.0000 1.0000
57.3200 67.0000 1.0000
57.3800 68.0000 1.0000
57.4400 64.0000 1.0000
57.5000 67.0000 1.0000
57.5600 68.0000 1.0000
57.6200 69.0000 1.0000
57.6800 63.0000 1.0000
57.7400 71.0000 1.0000
57.8000 63.0000 1.0000
57.8600 69.0000 1.0000
57.9200 67.0000 1.0000
57.9800 72.0000 1.0000
58.0400 67.0000 1.0000
58.1000 62.0000 1.0000
58.1600 68.0000 1.0000
58.2200 71.0000 1.0000
58.2800 62.0000 1.0000
58.3400 67.0000 1.0000
58.4000 80.0000 1.0000
58.4600 60.0000 1.0000
58.5200 73.0000 1.0000
58.5800 68.0000 1.0000
58.6400 74.0000 1.0000
58.7000 67.0000 1.0000
58.7600 62.0000 1.0000
58.8200 52.0000 1.0000
58.8800 64.0000 1.0000
58.9400 70.0000 1.0000
59.0000 69.0000 1.0000
59.0600 68.0000 1.0000
59.1200 72.0000 1.0000
59.1800 63.0000 1.0000
59.2400 84.0000 1.0000
59.3000 64.0000 1.0000
59.3600 62.0000 1.0000
59.4200 76.0000 1.0000
59.4800 66.0000 1.0000
59.5400 63.0000 1.0000
59.6000 65.0000 1.0000
59.6600 66.0000 1.0000
59.7200 75.0000 1.0000
59.7800 81.0000 1.0000
59.8400 81.0000 1.0000
59.9000 78.0000 1.0000
59.9600 73.0000 1.0000
60.0200 84.0000 1.0000
60.0800 76.0000 1.0000
60.1400 84.0000 1.0000
60.2000 73.0000 1.0000
60.2600 70.0000 1.0000
60.3200 68.0000 1.0000
60.3800 84.0000 1.0000
60.4400 68.0000 1.0000
60.5000 74.0000 1.0000
60.5600 61.0000 1.0000
60.6200 62.0000 1.0000
60.6800 75.0000 1.0000
60.7400 68.0000 1.0000
60.8000 70.0000 1.0000
60.8600 74.0000 1.0000
60.9200 70.0000 1.0000
60.9800 60.0000 1.0000
61.0400 64.0000 1.0000
61.1000 68.0000 1.0000
61.1600 59.0000 1.0000
61.2200 78.0000 1.0000
61.2800 68.0000 1.0000
61.3400 66.0000 1.0000
61.4000 61.0000 1.0000
61.4600 76.0000 1.0000
61.5200 65.0000 1.0000
61.5800 69.0000 1.0000
61.6400 66.0000 1.0000
61.7000 67.0000 1.0000
61.7600 63.0000 1.0000
61.8200 74.0000 1.0000
61.8800 71.0000 1.0000
61.9400 68.0000 1.0000
62.0000 70.0000 1.0000
62.0600 73.0000 1.0000
62.1200 80.0000 1.0000
62.1800 74.0000 1.0000
62.2400 93.0000 1.0000
62.3000 97.0000 1.0000
62.3600 142.0000 1.0000
62.4200 248.0000 1.0000
62.4800 248.0000 1.0000
62.5400 183.0000 1.0000
62.6000 193.0000 1.0000
62.6600 163.0000 1.0000
62.7200 125.0000 1.0000
62.7800 109.0000 1.0000
62.8400 89.0000 1.0000
62.9000 95.0000 1.0000
62.9600 74.0000 1.0000
63.0200 70.0000 1.0000
63.0800 83.0000 1.0000
63.1400 79.0000 1.0000
63.2000 89.0000 1.0000
63.2600 75.0000 1.0000
63.3200 70.0000 1.0000
63.3800 76.0000 1.0000
63.4400 84.0000 1.0000
63.5000 103.0000 1.0000
63.5600 121.0000 1.0000
63.6200 152.0000 1.0000
63.6800 226.0000 1.0000
63.7400 227.0000 1.0000
63.8000 172.0000 1.0000
63.8600 176.0000 1.0000
63.9200 146.0000 1.0000
63.9800 112.0000 1.0000
64.0400 99.0000 1.0000
64.1000 86.0000 1.0000
64.1600 79.0000 1.0000
64.2200 85.0000 1.0000
64.2800 80.0000 1.0000
64.3400 83.0000 1.0000
64.4000 99.0000 1.0000
64.4600 165.0000 1.0000
64.5200 171.0000 1.0000
64.5800 143.0000 1.0000
64.6400 121.0000 1.0000
64.7000 118.0000 1.0000
64.7600 100.0000 1.0000
64.8200 75.0000 1.0000
64.8800 71.0000 1.0000
64.9400 77.0000 1.0000
65.0000 66.0000 1.0000
65.0600 59.0000 1.0000
65.1200 70.0000 1.0000
65.1800 74.0000 1.0000
65.2400 76.0000 1.0000
65.3000 64.0000 1.0000
65.3600 72.0000 1.0000
65.4200 81.0000 1.0000
65.4800 71.0000 1.0000
65.5400 64.0000 1.0000
65.6000 67.0000 1.0000
65.6600 65.0000 1.0000
65.7200 70.0000 1.0000
65.7800 61.0000 1.0000
65.8400 69.0000 1.0000
65.9000 75.0000 1.0000
65.9600 63.0000 1.0000
66.0200 61.0000 1.0000
66.0800 69.0000 1.0000
66.1400 72.0000 1.0000
66.2000 68.0000 1.0000
66.2600 73.0000 1.0000
66.3200 66.0000 1.0000
66.3800 75.0000 1.0000
66.4400 71.0000 1.0000
66.5000 66.0000 1.0000
66.5600 68.0000 1.0000
66.6200 72.0000 1.0000
66.6800 69.0000 1.0000
66.7400 69.0000 1.0000
66.8000 71.0000 1.0000
66.8600 67.0000 1.0000
66.9200 75.0000 1.0000
66.9800 63.0000 1.0000
67.0400 65.0000 1.0000
67.1000 60.0000 1.0000
67.1600 57.0000 1.0000
67.2200 72.0000 1.0000
67.2800 60.0000 1.0000
67.3400 65.0000 1.0000
67.4000 59.0000 1.0000
67.4600 64.0000 1.0000
67.5200 69.0000 1.0000
67.5800 58.0000 1.0000
67.6400 67.0000 1.0000
67.7000 69.0000 1.0000
67.7600 63.0000 1.0000
67.8200 70.0000 1.0000
67.8800 69.0000 1.0000
67.9400 65.0000 1.0000
68.0000 56.0000 1.0000
68.0600 59.0000 1.0000
68.1200 65.0000 1.0000
68.1800 71.0000 1.0000
68.2400 71.0000 1.0000
68.3000 67.0000 1.0000
68.3600 66.0000 1.0000
68.4200 63.0000 1.0000
68.4800 63.0000 1.0000
68.5400 63.0000 1.0000
68.6000 59.0000 1.0000
68.6600 65.0000 1.0000
68.7200 64.0000 1.0000
68.7800 67.0000 1.0000
68.8400 73.0000 1.0000
68.9000 69.0000 1.0000
68.9600 67.0000 1.0000
69.0200 65.0000 1.0000
69.0800 75.0000 1.0000
69.1400 66.0000 1.0000
69.2000 67.0000 1.0000
69.2600 59.0000 1.0000
69.3200 61.0000 1.0000
69.3800 67.0000 1.0000
69.4400 75.0000 1.0000
69.5000 64.0000 1.0000
69.5600 68.0000 1.0000
69.6200 69.0000 1.0000
69.6800 63.0000 1.0000
69.7400 63.0000 1.0000
69.8000 72.0000 1.0000
69.8600 71.0000 1.0000
69.9200 63.0000 1.0000
69.9800 75.0000 1.0000
70.0400 65.0000 1.0000
70.1000 67.0000 1.0000
70.1600 68.0000 1.0000
70.2200 65.0000 1.0000
70.2800 65.0000 1.0000
70.3400 67.0000 1.0000
70.4000 70.0000 1.0000
70.4600 64.0000 1.0000
70.5200 78.0000 1.0000
70.5800 74.0000 1.0000
70.6400 89.0000 1.0000
70.7000 81.0000 1.0000
70.7600 92.0000 1.0000
70.8200 101.0000 1.0000
70.8800 81.0000 1.0000
70.9400 82.0000 1.0000
71.0000 83.0000 1.0000
71.0600 73.0000 1.0000
71.1200 69.0000 1.0000
71.1800 75.0000 1.0000
71.2400 75.0000 1.0000
71.3000 74.0000 1.0000
71.3600 66.0000 1.0000
71.4200 66.0000 1.0000
71.4800 74.0000 1.0000
71.5400 69.0000 1.0000
71.6000 67.0000 1.0000
71.6600 72.0000 1.0000
71.7200 64.0000 1.0000
71.7800 82.0000 1.0000
71.8400 69.0000 1.0000
71.9000 74.0000 1.0000
71.9600 70.0000 1.0000
72.0200 73.0000 1.0000
72.0800 65.0000 1.0000
72.1400 82.0000 1.0000
72.2000 99.0000 1.0000
72.2600 123.0000 1.0000
72.3200 172.0000 1.0000
72.3800 166.0000 1.0000
72.4400 126.0000 1.0000
72.5000 126.0000 1.0000
72.5600 124.0000 1.0000
72.6200 104.0000 1.0000
72.6800 72.0000 1.0000
72.7400 77.0000 1.0000
72.8000 78.0000 1.0000
72.8600 80.0000 1.0000
72.9200 81.0000 1.0000
72.9800 99.0000 1.0000
73.0400 146.0000 1.0000
73.1000 146.0000 1.0000
73.1600 118.0000 1.0000
73.2200 110.0000 1.0000
73.2800 111.0000 1.0000
73.3400 109.0000 1.0000
73.4000 92.0000 1.0000
73.4600 70.0000 1.0000
73.5200 70.0000 1.0000
73.5800 70.0000 1.0000
73.6400 56.0000 1.0000
73.7000 70.0000 1.0000
73.7600 63.0000 1.0000
73.8200 70.0000 1.0000
73.8800 63.0000 1.0000
73.9400 60.0000 1.0000
74.0000 59.0000 1.0000
74.0600 57.0000 1.0000
74.1200 57.0000 1.0000
74.1800 61.0000 1.0000
74.2400 66.0000 1.0000
74.3000 61.0000 1.0000
74.3600 60.0000 1.0000
74.4200 66.0000 1.0000
74.4800 71.0000 1.0000
74.5400 57.0000 1.0000
74.6000 67.0000 1.0000
74.6600 59.0000 1.0000
74.7200 58.0000 1.0000
74.7800 73.0000 1.0000
74.8400 57.0000 1.0000
74.9000 61.0000 1.0000
74.9600 55.0000 1.0000
75.0200 65.0000 1.0000
75.0800 66.0000 1.0000
75.1400 59.0000 1.0000
75.2000 68.0000 1.0000
75.2600 63.0000 1.0000
75.3200 58.0000 1.0000
75.3800 59.0000 1.0000
75.4400 65.0000 1.0000
75.5000 50.0000 1.0000
75.5600 60.0000 1.0000
75.6200 60.0000 1.0000
75.6800 52.0000 1.0000
75.7400 55.0000 1.0000
75.8000 51.0000 1.0000
75.8600 65.0000 1.0000
75.9200 53.0000 1.0000
75.9800 55.0000 1.0000
76.0400 61.0000 1.0000
76.1000 57.0000 1.0000
76.1600 62.0000 1.0000
76.2200 64.0000 1.0000
76.2800 57.0000 1.0000
76.3400 53.0000 1.0000
76.4000 64.0000 1.0000
76.4600 60.0000 1.0000
76.5200 59.0000 1.0000
76.5800 62.0000 1.0000
76.6400 64.0000 1.0000
76.7000 67.0000 1.0000
76.7600 63.0000 1.0000
76.8200 61.0000 1.0000
76.8800 65.0000 1.0000
76.9400 58.0000 1.0000
77.0000 64.0000 1.0000
77.0600 55.0000 1.0000
77.1200 64.0000 1.0000
77.1800 43.0000 1.0000
77.2400 55.0000 1.0000
77.3000 66.0000 1.0000
77.3600 51.0000 1.0000
77.4200 55.0000 1.0000
77.4800 58.0000 1.0000
77.5400 56.0000 1.0000
77.6000 57.0000 1.0000
77.6600 64.0000 1.0000
77.7200 59.0000 1.0000
77.7800 56.0000 1.0000
77.8400 54.0000 1.0000
77.9000 54.0000 1.0000
77.9600 56.0000 1.0000
78.0200 61.0000 1.0000
78.0800 53.0000 1.0000
78.1400 58.0000 1.0000
78.2000 56.0000 1.0000
78.2600 53.0000 1.0000
78.3200 57.0000 1.0000
78.3800 53.0000 1.0000
78.4400 68.0000 1.0000
78.5000 64.0000 1.0000
78.5600 76.0000 1.0000
78.6200 82.0000 1.0000
78.6800 79.0000 1.0000
78.7400 96.0000 1.0000
78.8000 93.0000 1.0000
78.8600 100.0000 1.0000
78.9200 101.0000 1.0000
78.9800 98.0000 1.0000
79.0400 89.0000 1.0000
79.1000 87.0000 1.0000
79.1600 93.0000 1.0000
79.2200 88.0000 1.0000
79.2800 101.0000 1.0000
79.3400 138.0000 1.0000
79.4000 155.0000 1.0000
79.4600 166.0000 1.0000
79.5200 119.0000 1.0000
79.5800 115.0000 1.0000
79.6400 115.0000 1.0000
79.7000 103.0000 1.0000
79.7600 83.0000 1.0000
79.8200 74.0000 1.0000
79.8800 61.0000 1.0000
79.9400 60.0000 1.0000
80.0000 61.0000 1.0000
80.0600 57.0000 1.0000
80.1200 55.0000 1.0000
80.1800 52.0000 1.0000
80.2400 59.0000 1.0000
80.3000 62.0000 1.0000
80.3600 58.0000 1.0000
80.4200 54.0000 1.0000
80.4800 58.0000 1.0000
80.5400 52.0000 1.0000
80.6000 59.0000 1.0000
80.6600 57.0000 1.0000
80.7200 48.0000 1.0000
80.7800 61.0000 1.0000
80.8400 58.0000 1.0000
80.9000 58.0000 1.0000
80.9600 48.0000 1.0000
81.0200 52.0000 1.0000
81.0800 57.0000 1.0000
81.1400 48.0000 1.0000
81.2000 50.0000 1.0000
81.2600 52.0000 1.0000
81.3200 46.0000 1.0000
81.3800 55.0000 1.0000
81.4400 59.0000 1.0000
81.5000 55.0000 1.0000
81.5600 63.0000 1.0000
81.6200 48.0000 1.0000
81.6800 53.0000 1.0000
81.7400 56.0000 1.0000
81.8000 54.0000 1.0000
81.8600 54.0000 1.0000
81.9200 53.0000 1.0000
81.9800 50.0000 1.0000
82.0400 62.0000 1.0000
82.1000 50.0000 1.0000
82.1600 51.0000 1.0000
82.2200 54.0000 1.0000
82.2800 63.0000 1.0000
82.3400 47.0000 1.0000
82.4000 51.0000 1.0000
82.4600 47.0000 1.0000
82.5200 60.0000 1.0000
82.5800 44.0000 1.0000
82.6400 55.0000 1.0000
82.7000 66.0000 1.0000
82.7600 54.0000 1.0000
82.8200 51.0000 1.0000
82.8800 52.0000 1.0000
82.9400 53.0000 1.0000
83.0000 46.0000 1.0000
83.0600 54.0000 1.0000
83.1200 46.0000 1.0000
83.1800 51.0000 1.0000
83.2400 56.0000 1.0000
83.3000 59.0000 1.0000
83.3600 50.0000 1.0000
83.4200 48.0000 1.0000
83.4800 67.0000 1.0000
83.5400 59.0000 1.0000
83.6000 51.0000 1.0000
83.6600 51.0000 1.0000
83.7200 49.0000 1.0000
83.7800 52.0000 1.0000
83.8400 49.0000 1.0000
83.9000 47.0000 1.0000
83.9600 41.0000 1.0000
84.0200 55.0000 1.0000
84.0800 48.0000 1.0000
84.1400 50.0000 1.0000
84.2000 48.0000 1.0000
84.2600 47.0000 1.0000
84.3200 44.0000 1.0000
84.3800 54.0000 1.0000
84.4400 48.0000 1.0000
84.5000 53.0000 1.0000
84.5600 61.0000 1.0000
84.6200 47.0000 1.0000
84.6800 44.0000 1.0000
84.7400 43.0000 1.0000
84.8000 51.0000 1.0000
84.8600 65.0000 1.0000
84.9200 48.0000 1.0000
84.9800 60.0000 1.0000
85.0400 55.0000 1.0000
85.1000 57.0000 1.0000
85.1600 44.0000 1.0000
85.2200 51.0000 1.0000
85.2800 57.0000 1.0000
85.3400 53.0000 1.0000
85.4000 49.0000 1.0000
85.4600 51.0000 1.0000
85.5200 59.0000 1.0000
85.5800 53.0000 1.0000
85.6400 41.0000 1.0000
85.7000 61.0000 1.0000
85.7600 56.0000 1.0000
85.8200 52.0000 1.0000
85.8800 44.0000 1.0000
85.9400 50.0000 1.0000
86.0000 47.0000 1.0000
86.0600 51.0000 1.0000
86.1200 45.0000 1.0000
86.1800 56.0000 1.0000
86.2400 50.0000 1.0000
86.3000 60.0000 1.0000
86.3600 45.0000 1.0000
86.4200 50.0000 1.0000
86.4800 45.0000 1.0000
86.5400 57.0000 1.0000
86.6000 50.0000 1.0000
86.6600 48.0000 1.0000
86.7200 59.0000 1.0000
86.7800 53.0000 1.0000
86.8400 48.0000 1.0000
86.9000 49.0000 1.0000
86.9600 52.0000 1.0000
87.0200 57.0000 1.0000
87.0800 52.0000 1.0000
87.1400 66.0000 1.0000
87.2000 51.0000 1.0000
87.2600 53.0000 1.0000
87.3200 51.0000 1.0000
87.3800 46.0000 1.0000
87.4400 49.0000 1.0000
87.5000 65.0000 1.0000
87.5600 56.0000 1.0000
87.6200 46.0000 1.0000
87.6800 66.0000 1.0000
87.7400 50.0000 1.0000
87.8000 48.0000 1.0000
87.8600 53.0000 1.0000
87.9200 49.0000 1.0000
87.9800 58.0000 1.0000
88.0400 60.0000 1.0000
88.1000 53.0000 1.0000
88.1600 51.0000 1.0000
88.2200 58.0000 1.0000
88.2800 57.0000 1.0000
88.3400 55.0000 1.0000
88.4000 58.0000 1.0000
88.4600 53.0000 1.0000
88.5200 51.0000 1.0000
88.5800 53.0000 1.0000
88.6400 56.0000 1.0000
88.7000 61.0000 1.0000
88.7600 51.0000 1.0000
88.8200 61.0000 1.0000
88.8800 61.0000 1.0000
88.9400 61.0000 1.0000
89.0000 64.0000 1.0000
89.0600 62.0000 1.0000
89.1200 62.0000 1.0000
89.1800 74.0000 1.0000
89.2400 87.0000 1.0000
89.3000 111.0000 1.0000
89.3600 133.0000 1.0000
89.4200 104.0000 1.0000
89.4800 78.0000 1.0000
89.5400 103.0000 1.0000
89.6000 93.0000 1.0000
89.6600 92.0000 1.0000
89.7200 77.0000 1.0000
89.7800 82.0000 1.0000
89.8400 74.0000 1.0000
89.9000 67.0000 1.0000
89.9600 71.0000 1.0000
90.0000 68.0000 1.0000
*RAS_INT_END
*RAS_DATA_END