File: xrd_umap_package_ja/data/cu-75%sn.1000rpm-1-1506-1_1.ras
*RAS_DATA_START
*RAS_HEADER_START
*CORR_POS_DB_NAME "Dtex_20210428"
*CORR_POS_GONIO_RADIUS ""
*CORR_POS_NODE_INDEX01 ""
*CORR_POS_NODE_INDEX02 ""
*CORR_POS_NODE_INDEX03 ""
*CORR_POS_NODE_INDEX04 ""
*CORR_POS_NODE_INDEX05 ""
*CORR_POS_NODE_INDEX06 ""
*CORR_POS_NODE_INDEX07 ""
*CORR_POS_NODE_INDEX08 ""
*CORR_POS_NODE_INDEX09 ""
*CORR_POS_NODE_INDEX10 ""
*CORR_POS_NODE_INDEX11 ""
*CORR_POS_NODE_LABEL01 "Si(111)"
*CORR_POS_NODE_LABEL02 "Si(220)"
*CORR_POS_NODE_LABEL03 "Si(311)"
*CORR_POS_NODE_LABEL04 "Si(400)"
*CORR_POS_NODE_LABEL05 "Si(331)"
*CORR_POS_NODE_LABEL06 "Si(422)"
*CORR_POS_NODE_LABEL07 "Si(511)"
*CORR_POS_NODE_LABEL08 "Si(440)"
*CORR_POS_NODE_LABEL09 "Si(531)"
*CORR_POS_NODE_LABEL10 "Si(620)"
*CORR_POS_NODE_LABEL11 "Si(533)"
*CORR_POS_NODE_POS_CALC01 "28.3773"
*CORR_POS_NODE_POS_CALC02 "47.2511"
*CORR_POS_NODE_POS_CALC03 "56.073"
*CORR_POS_NODE_POS_CALC04 "69.0829"
*CORR_POS_NODE_POS_CALC05 "76.3303"
*CORR_POS_NODE_POS_CALC06 "87.9864"
*CORR_POS_NODE_POS_CALC07 "94.9103"
*CORR_POS_NODE_POS_CALC08 "106.67"
*CORR_POS_NODE_POS_CALC09 "114.056"
*CORR_POS_NODE_POS_CALC10 "127.514"
*CORR_POS_NODE_POS_CALC11 "136.867"
*CORR_POS_NODE_POS_MEAS01 "28.4014"
*CORR_POS_NODE_POS_MEAS02 "47.2553"
*CORR_POS_NODE_POS_MEAS03 "56.0727"
*CORR_POS_NODE_POS_MEAS04 "69.0771"
*CORR_POS_NODE_POS_MEAS05 "76.3223"
*CORR_POS_NODE_POS_MEAS06 "87.9752"
*CORR_POS_NODE_POS_MEAS07 "94.897"
*CORR_POS_NODE_POS_MEAS08 "106.653"
*CORR_POS_NODE_POS_MEAS09 "114.038"
*CORR_POS_NODE_POS_MEAS10 "127.488"
*CORR_POS_NODE_POS_MEAS11 "136.841"
*CORR_POS_OPT_ATTR "集中法"
*CORR_POS_PARAM_MU ""
*CORR_POS_PARAM_PL ""
*CORR_POS_SEMODEL_TYPE "0"
*CORR_POS_STANDARD_TYPE ""
*CORR_POS_VALUE_ANALYZER "None"
*CORR_POS_VALUE_CMONO "None_None"
*CORR_POS_VALUE_IMONO "None"
*CORR_POS_VALUE_IS "1.250deg"
*CORR_POS_VALUE_ISL "10.0mm"
*CORR_POS_VALUE_ISOLLER "5.0deg"
*CORR_POS_VALUE_RS1 "13.0mm"
*CORR_POS_VALUE_RS2 "13.0mm"
*CORR_POS_VALUE_RSOLLER "5.0deg"
*CORR_POS_XG_FOCUS_L ""
*CORR_POS_XG_WAVE_TYPE ""
*CORR_POS_XG_WAVE_VALUE ""
*DISP_FMT_X "%.2f"
*DISP_FMT_Y "%.0f"
*DISP_FULLSCALE "204080.0000000000"
*DISP_LINE_COLOR "255.0000000000"
*DISP_LINE_STYLE "0.0000000000"
*DISP_LINE_WIDTH "0.2500000000"
*DISP_NOTE "測定データ-2"
*DISP_OFFSET_Y "0.0000000000"
*DISP_PEAKSEARCH_UNIT_Y "cps"
*DISP_RANGE_BOTTOM "0.0000000000"
*DISP_RANGE_LEFT "5.0000000000"
*DISP_RANGE_LOGCUTOFF "0.0100000000"
*DISP_RANGE_RIGHT "90.0000000000"
*DISP_RANGE_TOP "204080.0000000000"
*DISP_SCALE_MODE_Y "0.0000000000"
*DISP_TAB_NAME "2θ/θ"
*DISP_TITLE_Y "強度"
*DISP_UNIT_Y "cps"
*DISP_WINDOW_NAME "MSG_MACROENGINE"
*FILE_COMMENT " "
*FILE_MD5 ""
*FILE_MEMO " "
*FILE_OPERATOR "administrator"
*FILE_PART_ID "MEAS_PBEA_00223"
*FILE_SAMPLE "cu-75%sn.1000rpm"
*FILE_TYPE "RAS_RAW"
*FILE_USERGROUP "システムマネージャ"
*FILE_VERSION "1.0000000000"
*HW_ATTACHMENT_ID "ATT1025"
*HW_ATTACHMENT_NAME "標準試料台|Standard Sample Stage"
*HW_COUNTER_ID-0 "CUT0025"
*HW_COUNTER_ID-1 "CUT0020"
*HW_COUNTER_ID-2 "CUT0020"
*HW_COUNTER_ID-3 "CMC0021"
*HW_COUNTER_NAME-0 "D/teX Ultra2|D/teX Ultra2"
*HW_COUNTER_NAME-1 "None|None"
*HW_COUNTER_NAME-2 "None|None"
*HW_COUNTER_NAME-3 "検出器モノクロメータ|Detector monochromator"
*HW_COUNTER_SELECT_NAME "D/teX Ultra2|D/teX Ultra2"
*HW_GONIOMETER_ID "GON0070"
*HW_GONIOMETER_NAME "MiniFlex 300/600|MiniFlex 300/600"
*HW_GONIOMETER_RADIUS-0 "79.0"
*HW_GONIOMETER_RADIUS-1 "91.5"
*HW_GONIOMETER_RADIUS-2 "150.0"
*HW_GONIOMETER_RADIUS-3 "0"
*HW_GONIOMETER_RADIUS-4 "92.7"
*HW_GONIOMETER_RADIUS-5 "139.3"
*HW_GONIOMETER_RADIUS-6 "46.6"
*HW_GONIOMETER_RADIUS-7 "150.0"
*HW_I_OPT_ID-0 "ISL0021"
*HW_I_OPT_ID-1 "ISO0021"
*HW_I_OPT_NAME-0 "発散スリット|Divergence slit"
*HW_I_OPT_NAME-1 "入射平行スリット|Incident parallel slit"
*HW_R_ATTENUATER_AUTOMODE "0"
*HW_R_OPT_ID-0 "RSS0021"
*HW_R_OPT_ID-1 "RSO0021"
*HW_R_OPT_ID-2 "RRS0021"
*HW_R_OPT_NAME-0 "散乱スリット|Scattering slit"
*HW_R_OPT_NAME-1 "受光平行スリット|Receiving soller slit"
*HW_R_OPT_NAME-2 "受光スリット|Receiving slit"
*HW_SAMPLE_HOLDER_ID "SMP0000"
*HW_SAMPLE_HOLDER_NAME "無し|None"
*HW_XG_CURRENT_MAX "15"
*HW_XG_CURRENT_MIN "2"
*HW_XG_CURRENT_RESOLUTION "1"
*HW_XG_CURRENT_UNIT "mA"
*HW_XG_FOCUS "1mm x 10mm"
*HW_XG_FOCUS_TYPE "Normal"
*HW_XG_ID "1060"
*HW_XG_NAME "300W/600W 封入管-B|300W/600W Sealed tube-B"
*HW_XG_TARGET_ATOMIC_NUMBER "29.0000000000"
*HW_XG_TARGET_NAME "Cu"
*HW_XG_TYPE "Hermetic"
*HW_XG_VOLTAGE_MAX "40"
*HW_XG_VOLTAGE_MIN "20"
*HW_XG_VOLTAGE_RESOLUTION "1"
*HW_XG_VOLTAGE_UNIT "kV"
*HW_XG_WATT_MAX "1"
*HW_XG_WATT_UNIT "kW"
*HW_XG_WAVE_LENGTH_ALPHA1 "1.540593"
*HW_XG_WAVE_LENGTH_ALPHA2 "1.544414"
*HW_XG_WAVE_LENGTH_BETA "1.392250"
*MEAS_COND_AXIS_NAME-0 "2θ/θ"
*MEAS_COND_AXIS_NAME-1 "Soller(inc.)"
*MEAS_COND_AXIS_NAME-2 "IHS"
*MEAS_COND_AXIS_NAME-3 "DS"
*MEAS_COND_AXIS_NAME-4 "SS"
*MEAS_COND_AXIS_NAME-5 "Soller(rec.)"
*MEAS_COND_AXIS_NAME-6 "RS"
*MEAS_COND_AXIS_NAME-7 "フィルター"
*MEAS_COND_AXIS_NAME-8 "モノクロメータ"
*MEAS_COND_AXIS_NAME-9 "PHA"
*MEAS_COND_AXIS_NAME_INTERNAL-0 "TwoThetaTheta"
*MEAS_COND_AXIS_NAME_INTERNAL-1 "IncidentSollerSlit"
*MEAS_COND_AXIS_NAME_INTERNAL-2 "IncidentAxdSlit"
*MEAS_COND_AXIS_NAME_INTERNAL-3 "IncidentSlitBox"
*MEAS_COND_AXIS_NAME_INTERNAL-4 "ReceivingSlitBox1"
*MEAS_COND_AXIS_NAME_INTERNAL-5 "ReceivingSollerSlit"
*MEAS_COND_AXIS_NAME_INTERNAL-6 "ReceivingSlitBox2"
*MEAS_COND_AXIS_NAME_INTERNAL-7 "Filter"
*MEAS_COND_AXIS_NAME_INTERNAL-8 "CounterMonochromator"
*MEAS_COND_AXIS_NAME_INTERNAL-9 "PHA"
*MEAS_COND_AXIS_NAME_MAGICNO-0 "268632064.0000000000"
*MEAS_COND_AXIS_NAME_MAGICNO-1 "20971521.0000000000"
*MEAS_COND_AXIS_NAME_MAGICNO-2 "22020097.0000000000"
*MEAS_COND_AXIS_NAME_MAGICNO-3 "22020097.0000000000"
*MEAS_COND_AXIS_NAME_MAGICNO-4 "23068673.0000000000"
*MEAS_COND_AXIS_NAME_MAGICNO-5 "20971521.0000000000"
*MEAS_COND_AXIS_NAME_MAGICNO-6 "23068673.0000000000"
*MEAS_COND_AXIS_NAME_MAGICNO-7 "20971521.0000000000"
*MEAS_COND_AXIS_NAME_MAGICNO-8 "20971521.0000000000"
*MEAS_COND_AXIS_NAME_MAGICNO-9 "0.0000000000"
*MEAS_COND_AXIS_OFFSET-0 "0.0000000000"
*MEAS_COND_AXIS_OFFSET-1 "-"
*MEAS_COND_AXIS_OFFSET-2 "-"
*MEAS_COND_AXIS_OFFSET-3 "-"
*MEAS_COND_AXIS_OFFSET-4 "-"
*MEAS_COND_AXIS_OFFSET-5 "-"
*MEAS_COND_AXIS_OFFSET-6 "-"
*MEAS_COND_AXIS_OFFSET-7 "-"
*MEAS_COND_AXIS_OFFSET-8 "-"
*MEAS_COND_AXIS_OFFSET-9 "-"
*MEAS_COND_AXIS_POSITION-0 "12.0000000000"
*MEAS_COND_AXIS_POSITION-1 "5.0deg"
*MEAS_COND_AXIS_POSITION-2 "10.0mm"
*MEAS_COND_AXIS_POSITION-3 "1.250deg"
*MEAS_COND_AXIS_POSITION-4 "8.0mm"
*MEAS_COND_AXIS_POSITION-5 "5.0deg"
*MEAS_COND_AXIS_POSITION-6 "13.0mm(Open)"
*MEAS_COND_AXIS_POSITION-7 "K-beta(x2)"
*MEAS_COND_AXIS_POSITION-8 "None"
*MEAS_COND_AXIS_POSITION-9 "48.0000000000"
*MEAS_COND_AXIS_UNIT-0 "deg"
*MEAS_COND_AXIS_UNIT-1 ""
*MEAS_COND_AXIS_UNIT-2 ""
*MEAS_COND_AXIS_UNIT-3 ""
*MEAS_COND_AXIS_UNIT-4 ""
*MEAS_COND_AXIS_UNIT-5 ""
*MEAS_COND_AXIS_UNIT-6 ""
*MEAS_COND_AXIS_UNIT-7 ""
*MEAS_COND_AXIS_UNIT-8 ""
*MEAS_COND_AXIS_UNIT-9 "div"
*MEAS_COND_COUNTER_CNTLOSS_CORR "0.0000000000"
*MEAS_COND_COUNTER_PHABASE "48.0000000000"
*MEAS_COND_COUNTER_PHAWINDOW "9.0000000000"
*MEAS_COND_COUNTER_PHA_UNIT "div"
*MEAS_COND_COUNTER_TAUDIFF "0.2500000000"
*MEAS_COND_COUNTER_TAUINT "0.7500000000"
*MEAS_COND_IRRADIATION_MODE "OFF"
*MEAS_COND_IRRADIATION_WIDTH ""
*MEAS_COND_OPT_ATTR " "
*MEAS_COND_OPT_NAME ""
*MEAS_COND_UNSYMMETRIC_MODE "OFF"
*MEAS_COND_XG_CURRENT "15.0000000000"
*MEAS_COND_XG_VOLTAGE "40.0000000000"
*MEAS_COND_XG_WAVE_TYPE "Ka"
*MEAS_DATA_COUNT "8501.0000000000"
*MEAS_SCAN_AXIS_X "2θ/θ"
*MEAS_SCAN_AXIS_X_INTERNAL "TwoThetaTheta"
*MEAS_SCAN_END_TIME "04/09/24 15:11:50"
*MEAS_SCAN_MODE "CONTINUOUS"
*MEAS_SCAN_MONITOR "0"
*MEAS_SCAN_RESOLUTION_X "0.0025"
*MEAS_SCAN_SPEED "20.000000"
*MEAS_SCAN_SPEED_UNIT "deg/min"
*MEAS_SCAN_SPEED_USER "20.000000"
*MEAS_SCAN_START "5.0000000000"
*MEAS_SCAN_START_TIME "04/09/24 15:07:04"
*MEAS_SCAN_STEP "0.0100000000"
*MEAS_SCAN_STOP "90.0000000000"
*MEAS_SCAN_UNIT_X "deg"
*MEAS_SCAN_UNIT_Y "counts"
*SLIT_SYSTEM "0"
*RAS_HEADER_END
*RAS_INT_START
5.0000 227.0000 1.0000
5.0600 222.0000 1.0000
5.1200 239.0000 1.0000
5.1800 229.0000 1.0000
5.2400 226.0000 1.0000
5.3000 217.0000 1.0000
5.3600 229.0000 1.0000
5.4200 227.0000 1.0000
5.4800 222.0000 1.0000
5.5400 221.0000 1.0000
5.6000 232.0000 1.0000
5.6600 222.0000 1.0000
5.7200 224.0000 1.0000
5.7800 242.0000 1.0000
5.8400 246.0000 1.0000
5.9000 235.0000 1.0000
5.9600 236.0000 1.0000
6.0200 215.0000 1.0000
6.0800 222.0000 1.0000
6.1400 217.0000 1.0000
6.2000 223.0000 1.0000
6.2600 220.0000 1.0000
6.3200 217.0000 1.0000
6.3800 219.0000 1.0000
6.4400 242.0000 1.0000
6.5000 215.0000 1.0000
6.5600 227.0000 1.0000
6.6200 221.0000 1.0000
6.6800 230.0000 1.0000
6.7400 233.0000 1.0000
6.8000 234.0000 1.0000
6.8600 235.0000 1.0000
6.9200 222.0000 1.0000
6.9800 236.0000 1.0000
7.0400 245.0000 1.0000
7.1000 253.0000 1.0000
7.1600 241.0000 1.0000
7.2200 234.0000 1.0000
7.2800 242.0000 1.0000
7.3400 237.0000 1.0000
7.4000 240.0000 1.0000
7.4600 227.0000 1.0000
7.5200 269.0000 1.0000
7.5800 248.0000 1.0000
7.6400 215.0000 1.0000
7.7000 235.0000 1.0000
7.7600 245.0000 1.0000
7.8200 246.0000 1.0000
7.8800 261.0000 1.0000
7.9400 251.0000 1.0000
8.0000 241.0000 1.0000
8.0600 268.0000 1.0000
8.1200 253.0000 1.0000
8.1800 248.0000 1.0000
8.2400 246.0000 1.0000
8.3000 270.0000 1.0000
8.3600 254.0000 1.0000
8.4200 264.0000 1.0000
8.4800 260.0000 1.0000
8.5400 234.0000 1.0000
8.6000 263.0000 1.0000
8.6600 250.0000 1.0000
8.7200 265.0000 1.0000
8.7800 254.0000 1.0000
8.8400 253.0000 1.0000
8.9000 234.0000 1.0000
8.9600 250.0000 1.0000
9.0200 264.0000 1.0000
9.0800 267.0000 1.0000
9.1400 269.0000 1.0000
9.2000 269.0000 1.0000
9.2600 252.0000 1.0000
9.3200 266.0000 1.0000
9.3800 274.0000 1.0000
9.4400 287.0000 1.0000
9.5000 249.0000 1.0000
9.5600 256.0000 1.0000
9.6200 271.0000 1.0000
9.6800 280.0000 1.0000
9.7400 276.0000 1.0000
9.8000 264.0000 1.0000
9.8600 253.0000 1.0000
9.9200 272.0000 1.0000
9.9800 267.0000 1.0000
10.0400 288.0000 1.0000
10.1000 271.0000 1.0000
10.1600 281.0000 1.0000
10.2200 286.0000 1.0000
10.2800 301.0000 1.0000
10.3400 267.0000 1.0000
10.4000 277.0000 1.0000
10.4600 299.0000 1.0000
10.5200 290.0000 1.0000
10.5800 293.0000 1.0000
10.6400 271.0000 1.0000
10.7000 304.0000 1.0000
10.7600 274.0000 1.0000
10.8200 272.0000 1.0000
10.8800 282.0000 1.0000
10.9400 301.0000 1.0000
11.0000 298.0000 1.0000
11.0600 275.0000 1.0000
11.1200 291.0000 1.0000
11.1800 286.0000 1.0000
11.2400 288.0000 1.0000
11.3000 265.0000 1.0000
11.3600 302.0000 1.0000
11.4200 290.0000 1.0000
11.4800 284.0000 1.0000
11.5400 307.0000 1.0000
11.6000 279.0000 1.0000
11.6600 290.0000 1.0000
11.7200 272.0000 1.0000
11.7800 313.0000 1.0000
11.8400 289.0000 1.0000
11.9000 283.0000 1.0000
11.9600 299.0000 1.0000
12.0200 267.0000 1.0000
12.0800 300.0000 1.0000
12.1400 296.0000 1.0000
12.2000 279.0000 1.0000
12.2600 291.0000 1.0000
12.3200 295.0000 1.0000
12.3800 299.0000 1.0000
12.4400 294.0000 1.0000
12.5000 293.0000 1.0000
12.5600 304.0000 1.0000
12.6200 297.0000 1.0000
12.6800 297.0000 1.0000
12.7400 289.0000 1.0000
12.8000 294.0000 1.0000
12.8600 309.0000 1.0000
12.9200 332.0000 1.0000
12.9800 292.0000 1.0000
13.0400 283.0000 1.0000
13.1000 297.0000 1.0000
13.1600 300.0000 1.0000
13.2200 284.0000 1.0000
13.2800 305.0000 1.0000
13.3400 320.0000 1.0000
13.4000 313.0000 1.0000
13.4600 317.0000 1.0000
13.5200 309.0000 1.0000
13.5800 292.0000 1.0000
13.6400 290.0000 1.0000
13.7000 314.0000 1.0000
13.7600 286.0000 1.0000
13.8200 265.0000 1.0000
13.8800 291.0000 1.0000
13.9400 295.0000 1.0000
14.0000 298.0000 1.0000
14.0600 293.0000 1.0000
14.1200 284.0000 1.0000
14.1800 279.0000 1.0000
14.2400 280.0000 1.0000
14.3000 301.0000 1.0000
14.3600 291.0000 1.0000
14.4200 275.0000 1.0000
14.4800 285.0000 1.0000
14.5400 298.0000 1.0000
14.6000 312.0000 1.0000
14.6600 291.0000 1.0000
14.7200 285.0000 1.0000
14.7800 320.0000 1.0000
14.8400 305.0000 1.0000
14.9000 313.0000 1.0000
14.9600 305.0000 1.0000
15.0200 307.0000 1.0000
15.0800 297.0000 1.0000
15.1400 310.0000 1.0000
15.2000 292.0000 1.0000
15.2600 286.0000 1.0000
15.3200 294.0000 1.0000
15.3800 265.0000 1.0000
15.4400 307.0000 1.0000
15.5000 273.0000 1.0000
15.5600 292.0000 1.0000
15.6200 284.0000 1.0000
15.6800 279.0000 1.0000
15.7400 280.0000 1.0000
15.8000 270.0000 1.0000
15.8600 284.0000 1.0000
15.9200 282.0000 1.0000
15.9800 283.0000 1.0000
16.0400 301.0000 1.0000
16.1000 296.0000 1.0000
16.1600 285.0000 1.0000
16.2200 282.0000 1.0000
16.2800 261.0000 1.0000
16.3400 285.0000 1.0000
16.4000 301.0000 1.0000
16.4600 298.0000 1.0000
16.5200 290.0000 1.0000
16.5800 291.0000 1.0000
16.6400 264.0000 1.0000
16.7000 269.0000 1.0000
16.7600 271.0000 1.0000
16.8200 273.0000 1.0000
16.8800 285.0000 1.0000
16.9400 304.0000 1.0000
17.0000 266.0000 1.0000
17.0600 278.0000 1.0000
17.1200 272.0000 1.0000
17.1800 278.0000 1.0000
17.2400 270.0000 1.0000
17.3000 264.0000 1.0000
17.3600 253.0000 1.0000
17.4200 271.0000 1.0000
17.4800 268.0000 1.0000
17.5400 276.0000 1.0000
17.6000 283.0000 1.0000
17.6600 277.0000 1.0000
17.7200 280.0000 1.0000
17.7800 278.0000 1.0000
17.8400 264.0000 1.0000
17.9000 263.0000 1.0000
17.9600 276.0000 1.0000
18.0200 269.0000 1.0000
18.0800 256.0000 1.0000
18.1400 274.0000 1.0000
18.2000 258.0000 1.0000
18.2600 278.0000 1.0000
18.3200 249.0000 1.0000
18.3800 271.0000 1.0000
18.4400 264.0000 1.0000
18.5000 274.0000 1.0000
18.5600 257.0000 1.0000
18.6200 288.0000 1.0000
18.6800 249.0000 1.0000
18.7400 261.0000 1.0000
18.8000 249.0000 1.0000
18.8600 266.0000 1.0000
18.9200 273.0000 1.0000
18.9800 253.0000 1.0000
19.0400 245.0000 1.0000
19.1000 244.0000 1.0000
19.1600 232.0000 1.0000
19.2200 258.0000 1.0000
19.2800 244.0000 1.0000
19.3400 261.0000 1.0000
19.4000 247.0000 1.0000
19.4600 261.0000 1.0000
19.5200 260.0000 1.0000
19.5800 234.0000 1.0000
19.6400 235.0000 1.0000
19.7000 256.0000 1.0000
19.7600 250.0000 1.0000
19.8200 244.0000 1.0000
19.8800 227.0000 1.0000
19.9400 247.0000 1.0000
20.0000 242.0000 1.0000
20.0600 237.0000 1.0000
20.1200 227.0000 1.0000
20.1800 240.0000 1.0000
20.2400 221.0000 1.0000
20.3000 228.0000 1.0000
20.3600 259.0000 1.0000
20.4200 245.0000 1.0000
20.4800 237.0000 1.0000
20.5400 226.0000 1.0000
20.6000 238.0000 1.0000
20.6600 237.0000 1.0000
20.7200 233.0000 1.0000
20.7800 227.0000 1.0000
20.8400 236.0000 1.0000
20.9000 223.0000 1.0000
20.9600 213.0000 1.0000
21.0200 224.0000 1.0000
21.0800 216.0000 1.0000
21.1400 227.0000 1.0000
21.2000 212.0000 1.0000
21.2600 216.0000 1.0000
21.3200 220.0000 1.0000
21.3800 211.0000 1.0000
21.4400 218.0000 1.0000
21.5000 210.0000 1.0000
21.5600 205.0000 1.0000
21.6200 207.0000 1.0000
21.6800 218.0000 1.0000
21.7400 218.0000 1.0000
21.8000 195.0000 1.0000
21.8600 207.0000 1.0000
21.9200 203.0000 1.0000
21.9800 212.0000 1.0000
22.0400 226.0000 1.0000
22.1000 195.0000 1.0000
22.1600 206.0000 1.0000
22.2200 207.0000 1.0000
22.2800 206.0000 1.0000
22.3400 224.0000 1.0000
22.4000 210.0000 1.0000
22.4600 215.0000 1.0000
22.5200 201.0000 1.0000
22.5800 203.0000 1.0000
22.6400 183.0000 1.0000
22.7000 208.0000 1.0000
22.7600 203.0000 1.0000
22.8200 200.0000 1.0000
22.8800 197.0000 1.0000
22.9400 186.0000 1.0000
23.0000 200.0000 1.0000
23.0600 174.0000 1.0000
23.1200 195.0000 1.0000
23.1800 195.0000 1.0000
23.2400 206.0000 1.0000
23.3000 185.0000 1.0000
23.3600 187.0000 1.0000
23.4200 192.0000 1.0000
23.4800 188.0000 1.0000
23.5400 178.0000 1.0000
23.6000 192.0000 1.0000
23.6600 182.0000 1.0000
23.7200 203.0000 1.0000
23.7800 187.0000 1.0000
23.8400 189.0000 1.0000
23.9000 161.0000 1.0000
23.9600 179.0000 1.0000
24.0200 188.0000 1.0000
24.0800 194.0000 1.0000
24.1400 183.0000 1.0000
24.2000 168.0000 1.0000
24.2600 170.0000 1.0000
24.3200 166.0000 1.0000
24.3800 177.0000 1.0000
24.4400 162.0000 1.0000
24.5000 168.0000 1.0000
24.5600 167.0000 1.0000
24.6200 187.0000 1.0000
24.6800 180.0000 1.0000
24.7400 175.0000 1.0000
24.8000 183.0000 1.0000
24.8600 169.0000 1.0000
24.9200 177.0000 1.0000
24.9800 167.0000 1.0000
25.0400 192.0000 1.0000
25.1000 174.0000 1.0000
25.1600 180.0000 1.0000
25.2200 161.0000 1.0000
25.2800 157.0000 1.0000
25.3400 172.0000 1.0000
25.4000 176.0000 1.0000
25.4600 172.0000 1.0000
25.5200 168.0000 1.0000
25.5800 165.0000 1.0000
25.6400 161.0000 1.0000
25.7000 171.0000 1.0000
25.7600 168.0000 1.0000
25.8200 168.0000 1.0000
25.8800 179.0000 1.0000
25.9400 158.0000 1.0000
26.0000 167.0000 1.0000
26.0600 149.0000 1.0000
26.1200 152.0000 1.0000
26.1800 164.0000 1.0000
26.2400 173.0000 1.0000
26.3000 155.0000 1.0000
26.3600 168.0000 1.0000
26.4200 154.0000 1.0000
26.4800 156.0000 1.0000
26.5400 141.0000 1.0000
26.6000 149.0000 1.0000
26.6600 153.0000 1.0000
26.7200 158.0000 1.0000
26.7800 166.0000 1.0000
26.8400 145.0000 1.0000
26.9000 144.0000 1.0000
26.9600 160.0000 1.0000
27.0200 151.0000 1.0000
27.0800 146.0000 1.0000
27.1400 145.0000 1.0000
27.2000 154.0000 1.0000
27.2600 154.0000 1.0000
27.3200 155.0000 1.0000
27.3800 156.0000 1.0000
27.4400 148.0000 1.0000
27.5000 152.0000 1.0000
27.5600 159.0000 1.0000
27.6200 150.0000 1.0000
27.6800 158.0000 1.0000
27.7400 139.0000 1.0000
27.8000 152.0000 1.0000
27.8600 135.0000 1.0000
27.9200 140.0000 1.0000
27.9800 152.0000 1.0000
28.0400 155.0000 1.0000
28.1000 148.0000 1.0000
28.1600 145.0000 1.0000
28.2200 135.0000 1.0000
28.2800 145.0000 1.0000
28.3400 140.0000 1.0000
28.4000 157.0000 1.0000
28.4600 128.0000 1.0000
28.5200 145.0000 1.0000
28.5800 148.0000 1.0000
28.6400 151.0000 1.0000
28.7000 149.0000 1.0000
28.7600 146.0000 1.0000
28.8200 145.0000 1.0000
28.8800 138.0000 1.0000
28.9400 140.0000 1.0000
29.0000 149.0000 1.0000
29.0600 147.0000 1.0000
29.1200 159.0000 1.0000
29.1800 142.0000 1.0000
29.2400 151.0000 1.0000
29.3000 156.0000 1.0000
29.3600 148.0000 1.0000
29.4200 151.0000 1.0000
29.4800 171.0000 1.0000
29.5400 195.0000 1.0000
29.6000 188.0000 1.0000
29.6600 194.0000 1.0000
29.7200 199.0000 1.0000
29.7800 248.0000 1.0000
29.8400 326.0000 1.0000
29.9000 445.0000 1.0000
29.9600 746.0000 1.0000
30.0200 1001.0000 1.0000
30.0800 1023.0000 1.0000
30.1400 805.0000 1.0000
30.2000 580.0000 1.0000
30.2600 451.0000 1.0000
30.3200 500.0000 1.0000
30.3800 737.0000 1.0000
30.4400 1490.0000 1.0000
30.5000 3368.0000 1.0000
30.5600 5092.0000 1.0000
30.6200 3765.0000 1.0000
30.6800 1837.0000 1.0000
30.7400 741.0000 1.0000
30.8000 442.0000 1.0000
30.8600 324.0000 1.0000
30.9200 261.0000 1.0000
30.9800 237.0000 1.0000
31.0400 203.0000 1.0000
31.1000 189.0000 1.0000
31.1600 174.0000 1.0000
31.2200 165.0000 1.0000
31.2800 195.0000 1.0000
31.3400 186.0000 1.0000
31.4000 188.0000 1.0000
31.4600 182.0000 1.0000
31.5200 214.0000 1.0000
31.5800 202.0000 1.0000
31.6400 226.0000 1.0000
31.7000 285.0000 1.0000
31.7600 386.0000 1.0000
31.8200 759.0000 1.0000
31.8800 1673.0000 1.0000
31.9400 2453.0000 1.0000
32.0000 1512.0000 1.0000
32.0600 743.0000 1.0000
32.1200 274.0000 1.0000
32.1800 236.0000 1.0000
32.2400 212.0000 1.0000
32.3000 185.0000 1.0000
32.3600 169.0000 1.0000
32.4200 155.0000 1.0000
32.4800 142.0000 1.0000
32.5400 153.0000 1.0000
32.6000 147.0000 1.0000
32.6600 137.0000 1.0000
32.7200 137.0000 1.0000
32.7800 140.0000 1.0000
32.8400 147.0000 1.0000
32.9000 131.0000 1.0000
32.9600 129.0000 1.0000
33.0200 133.0000 1.0000
33.0800 132.0000 1.0000
33.1400 125.0000 1.0000
33.2000 126.0000 1.0000
33.2600 130.0000 1.0000
33.3200 114.0000 1.0000
33.3800 122.0000 1.0000
33.4400 135.0000 1.0000
33.5000 118.0000 1.0000
33.5600 127.0000 1.0000
33.6200 129.0000 1.0000
33.6800 124.0000 1.0000
33.7400 133.0000 1.0000
33.8000 131.0000 1.0000
33.8600 125.0000 1.0000
33.9200 124.0000 1.0000
33.9800 127.0000 1.0000
34.0400 114.0000 1.0000
34.1000 132.0000 1.0000
34.1600 117.0000 1.0000
34.2200 116.0000 1.0000
34.2800 127.0000 1.0000
34.3400 106.0000 1.0000
34.4000 112.0000 1.0000
34.4600 110.0000 1.0000
34.5200 125.0000 1.0000
34.5800 121.0000 1.0000
34.6400 111.0000 1.0000
34.7000 120.0000 1.0000
34.7600 113.0000 1.0000
34.8200 114.0000 1.0000
34.8800 111.0000 1.0000
34.9400 111.0000 1.0000
35.0000 134.0000 1.0000
35.0600 136.0000 1.0000
35.1200 134.0000 1.0000
35.1800 146.0000 1.0000
35.2400 123.0000 1.0000
35.3000 113.0000 1.0000
35.3600 116.0000 1.0000
35.4200 108.0000 1.0000
35.4800 98.0000 1.0000
35.5400 113.0000 1.0000
35.6000 124.0000 1.0000
35.6600 116.0000 1.0000
35.7200 110.0000 1.0000
35.7800 103.0000 1.0000
35.8400 104.0000 1.0000
35.9000 116.0000 1.0000
35.9600 124.0000 1.0000
36.0200 99.0000 1.0000
36.0800 102.0000 1.0000
36.1400 111.0000 1.0000
36.2000 107.0000 1.0000
36.2600 101.0000 1.0000
36.3200 113.0000 1.0000
36.3800 102.0000 1.0000
36.4400 104.0000 1.0000
36.5000 108.0000 1.0000
36.5600 86.0000 1.0000
36.6200 104.0000 1.0000
36.6800 113.0000 1.0000
36.7400 98.0000 1.0000
36.8000 102.0000 1.0000
36.8600 116.0000 1.0000
36.9200 108.0000 1.0000
36.9800 95.0000 1.0000
37.0400 103.0000 1.0000
37.1000 102.0000 1.0000
37.1600 110.0000 1.0000
37.2200 95.0000 1.0000
37.2800 124.0000 1.0000
37.3400 111.0000 1.0000
37.4000 104.0000 1.0000
37.4600 112.0000 1.0000
37.5200 108.0000 1.0000
37.5800 114.0000 1.0000
37.6400 89.0000 1.0000
37.7000 109.0000 1.0000
37.7600 107.0000 1.0000
37.8200 101.0000 1.0000
37.8800 103.0000 1.0000
37.9400 93.0000 1.0000
38.0000 109.0000 1.0000
38.0600 111.0000 1.0000
38.1200 107.0000 1.0000
38.1800 104.0000 1.0000
38.2400 114.0000 1.0000
38.3000 110.0000 1.0000
38.3600 108.0000 1.0000
38.4200 97.0000 1.0000
38.4800 105.0000 1.0000
38.5400 108.0000 1.0000
38.6000 113.0000 1.0000
38.6600 96.0000 1.0000
38.7200 107.0000 1.0000
38.7800 108.0000 1.0000
38.8400 95.0000 1.0000
38.9000 104.0000 1.0000
38.9600 108.0000 1.0000
39.0200 95.0000 1.0000
39.0800 95.0000 1.0000
39.1400 110.0000 1.0000
39.2000 110.0000 1.0000
39.2600 91.0000 1.0000
39.3200 106.0000 1.0000
39.3800 95.0000 1.0000
39.4400 109.0000 1.0000
39.5000 109.0000 1.0000
39.5600 104.0000 1.0000
39.6200 110.0000 1.0000
39.6800 122.0000 1.0000
39.7400 102.0000 1.0000
39.8000 106.0000 1.0000
39.8600 117.0000 1.0000
39.9200 102.0000 1.0000
39.9800 100.0000 1.0000
40.0400 106.0000 1.0000
40.1000 108.0000 1.0000
40.1600 91.0000 1.0000
40.2200 117.0000 1.0000
40.2800 94.0000 1.0000
40.3400 97.0000 1.0000
40.4000 96.0000 1.0000
40.4600 116.0000 1.0000
40.5200 104.0000 1.0000
40.5800 91.0000 1.0000
40.6400 96.0000 1.0000
40.7000 87.0000 1.0000
40.7600 98.0000 1.0000
40.8200 101.0000 1.0000
40.8800 95.0000 1.0000
40.9400 98.0000 1.0000
41.0000 99.0000 1.0000
41.0600 91.0000 1.0000
41.1200 96.0000 1.0000
41.1800 91.0000 1.0000
41.2400 111.0000 1.0000
41.3000 93.0000 1.0000
41.3600 97.0000 1.0000
41.4200 95.0000 1.0000
41.4800 105.0000 1.0000
41.5400 107.0000 1.0000
41.6000 108.0000 1.0000
41.6600 106.0000 1.0000
41.7200 104.0000 1.0000
41.7800 104.0000 1.0000
41.8400 98.0000 1.0000
41.9000 88.0000 1.0000
41.9600 98.0000 1.0000
42.0200 107.0000 1.0000
42.0800 98.0000 1.0000
42.1400 95.0000 1.0000
42.2000 97.0000 1.0000
42.2600 103.0000 1.0000
42.3200 120.0000 1.0000
42.3800 116.0000 1.0000
42.4400 139.0000 1.0000
42.5000 129.0000 1.0000
42.5600 143.0000 1.0000
42.6200 167.0000 1.0000
42.6800 236.0000 1.0000
42.7400 348.0000 1.0000
42.8000 533.0000 1.0000
42.8600 670.0000 1.0000
42.9200 647.0000 1.0000
42.9800 571.0000 1.0000
43.0400 458.0000 1.0000
43.1000 459.0000 1.0000
43.1600 501.0000 1.0000
43.2200 483.0000 1.0000
43.2800 430.0000 1.0000
43.3400 329.0000 1.0000
43.4000 233.0000 1.0000
43.4600 186.0000 1.0000
43.5200 139.0000 1.0000
43.5800 138.0000 1.0000
43.6400 172.0000 1.0000
43.7000 230.0000 1.0000
43.7600 436.0000 1.0000
43.8200 481.0000 1.0000
43.8800 325.0000 1.0000
43.9400 274.0000 1.0000
44.0000 163.0000 1.0000
44.0600 143.0000 1.0000
44.1200 115.0000 1.0000
44.1800 112.0000 1.0000
44.2400 105.0000 1.0000
44.3000 115.0000 1.0000
44.3600 123.0000 1.0000
44.4200 122.0000 1.0000
44.4800 134.0000 1.0000
44.5400 148.0000 1.0000
44.6000 172.0000 1.0000
44.6600 225.0000 1.0000
44.7200 402.0000 1.0000
44.7800 870.0000 1.0000
44.8400 1017.0000 1.0000
44.9000 676.0000 1.0000
44.9600 531.0000 1.0000
45.0200 263.0000 1.0000
45.0800 170.0000 1.0000
45.1400 136.0000 1.0000
45.2000 110.0000 1.0000
45.2600 121.0000 1.0000
45.3200 116.0000 1.0000
45.3800 98.0000 1.0000
45.4400 102.0000 1.0000
45.5000 85.0000 1.0000
45.5600 99.0000 1.0000
45.6200 97.0000 1.0000
45.6800 94.0000 1.0000
45.7400 99.0000 1.0000
45.8000 100.0000 1.0000
45.8600 90.0000 1.0000
45.9200 96.0000 1.0000
45.9800 102.0000 1.0000
46.0400 92.0000 1.0000
46.1000 103.0000 1.0000
46.1600 89.0000 1.0000
46.2200 93.0000 1.0000
46.2800 91.0000 1.0000
46.3400 89.0000 1.0000
46.4000 98.0000 1.0000
46.4600 92.0000 1.0000
46.5200 93.0000 1.0000
46.5800 104.0000 1.0000
46.6400 84.0000 1.0000
46.7000 99.0000 1.0000
46.7600 93.0000 1.0000
46.8200 96.0000 1.0000
46.8800 81.0000 1.0000
46.9400 98.0000 1.0000
47.0000 92.0000 1.0000
47.0600 88.0000 1.0000
47.1200 97.0000 1.0000
47.1800 98.0000 1.0000
47.2400 94.0000 1.0000
47.3000 96.0000 1.0000
47.3600 105.0000 1.0000
47.4200 97.0000 1.0000
47.4800 102.0000 1.0000
47.5400 84.0000 1.0000
47.6000 87.0000 1.0000
47.6600 96.0000 1.0000
47.7200 83.0000 1.0000
47.7800 88.0000 1.0000
47.8400 82.0000 1.0000
47.9000 88.0000 1.0000
47.9600 98.0000 1.0000
48.0200 79.0000 1.0000
48.0800 90.0000 1.0000
48.1400 88.0000 1.0000
48.2000 79.0000 1.0000
48.2600 91.0000 1.0000
48.3200 85.0000 1.0000
48.3800 94.0000 1.0000
48.4400 92.0000 1.0000
48.5000 85.0000 1.0000
48.5600 89.0000 1.0000
48.6200 94.0000 1.0000
48.6800 91.0000 1.0000
48.7400 91.0000 1.0000
48.8000 82.0000 1.0000
48.8600 97.0000 1.0000
48.9200 78.0000 1.0000
48.9800 98.0000 1.0000
49.0400 88.0000 1.0000
49.1000 91.0000 1.0000
49.1600 83.0000 1.0000
49.2200 88.0000 1.0000
49.2800 70.0000 1.0000
49.3400 85.0000 1.0000
49.4000 90.0000 1.0000
49.4600 83.0000 1.0000
49.5200 104.0000 1.0000
49.5800 95.0000 1.0000
49.6400 88.0000 1.0000
49.7000 70.0000 1.0000
49.7600 81.0000 1.0000
49.8200 99.0000 1.0000
49.8800 92.0000 1.0000
49.9400 87.0000 1.0000
50.0000 79.0000 1.0000
50.0600 91.0000 1.0000
50.1200 90.0000 1.0000
50.1800 87.0000 1.0000
50.2400 87.0000 1.0000
50.3000 94.0000 1.0000
50.3600 93.0000 1.0000
50.4200 82.0000 1.0000
50.4800 78.0000 1.0000
50.5400 91.0000 1.0000
50.6000 79.0000 1.0000
50.6600 75.0000 1.0000
50.7200 100.0000 1.0000
50.7800 82.0000 1.0000
50.8400 85.0000 1.0000
50.9000 93.0000 1.0000
50.9600 90.0000 1.0000
51.0200 93.0000 1.0000
51.0800 86.0000 1.0000
51.1400 82.0000 1.0000
51.2000 85.0000 1.0000
51.2600 91.0000 1.0000
51.3200 80.0000 1.0000
51.3800 82.0000 1.0000
51.4400 98.0000 1.0000
51.5000 90.0000 1.0000
51.5600 86.0000 1.0000
51.6200 98.0000 1.0000
51.6800 95.0000 1.0000
51.7400 86.0000 1.0000
51.8000 77.0000 1.0000
51.8600 80.0000 1.0000
51.9200 91.0000 1.0000
51.9800 84.0000 1.0000
52.0400 93.0000 1.0000
52.1000 78.0000 1.0000
52.1600 94.0000 1.0000
52.2200 85.0000 1.0000
52.2800 88.0000 1.0000
52.3400 94.0000 1.0000
52.4000 88.0000 1.0000
52.4600 81.0000 1.0000
52.5200 94.0000 1.0000
52.5800 92.0000 1.0000
52.6400 102.0000 1.0000
52.7000 99.0000 1.0000
52.7600 106.0000 1.0000
52.8200 90.0000 1.0000
52.8800 101.0000 1.0000
52.9400 101.0000 1.0000
53.0000 118.0000 1.0000
53.0600 120.0000 1.0000
53.1200 115.0000 1.0000
53.1800 160.0000 1.0000
53.2400 195.0000 1.0000
53.3000 192.0000 1.0000
53.3600 178.0000 1.0000
53.4200 173.0000 1.0000
53.4800 155.0000 1.0000
53.5400 119.0000 1.0000
53.6000 111.0000 1.0000
53.6600 112.0000 1.0000
53.7200 88.0000 1.0000
53.7800 95.0000 1.0000
53.8400 92.0000 1.0000
53.9000 89.0000 1.0000
53.9600 93.0000 1.0000
54.0200 108.0000 1.0000
54.0800 96.0000 1.0000
54.1400 84.0000 1.0000
54.2000 95.0000 1.0000
54.2600 97.0000 1.0000
54.3200 94.0000 1.0000
54.3800 90.0000 1.0000
54.4400 84.0000 1.0000
54.5000 95.0000 1.0000
54.5600 100.0000 1.0000
54.6200 83.0000 1.0000
54.6800 84.0000 1.0000
54.7400 84.0000 1.0000
54.8000 91.0000 1.0000
54.8600 92.0000 1.0000
54.9200 109.0000 1.0000
54.9800 119.0000 1.0000
55.0400 130.0000 1.0000
55.1000 161.0000 1.0000
55.1600 235.0000 1.0000
55.2200 384.0000 1.0000
55.2800 489.0000 1.0000
55.3400 382.0000 1.0000
55.4000 328.0000 1.0000
55.4600 276.0000 1.0000
55.5200 168.0000 1.0000
55.5800 127.0000 1.0000
55.6400 117.0000 1.0000
55.7000 108.0000 1.0000
55.7600 99.0000 1.0000
55.8200 106.0000 1.0000
55.8800 97.0000 1.0000
55.9400 95.0000 1.0000
56.0000 96.0000 1.0000
56.0600 93.0000 1.0000
56.1200 109.0000 1.0000
56.1800 105.0000 1.0000
56.2400 97.0000 1.0000
56.3000 107.0000 1.0000
56.3600 107.0000 1.0000
56.4200 115.0000 1.0000
56.4800 108.0000 1.0000
56.5400 117.0000 1.0000
56.6000 131.0000 1.0000
56.6600 130.0000 1.0000
56.7200 125.0000 1.0000
56.7800 109.0000 1.0000
56.8400 111.0000 1.0000
56.9000 108.0000 1.0000
56.9600 114.0000 1.0000
57.0200 102.0000 1.0000
57.0800 96.0000 1.0000
57.1400 93.0000 1.0000
57.2000 91.0000 1.0000
57.2600 81.0000 1.0000
57.3200 103.0000 1.0000
57.3800 87.0000 1.0000
57.4400 107.0000 1.0000
57.5000 94.0000 1.0000
57.5600 103.0000 1.0000
57.6200 98.0000 1.0000
57.6800 102.0000 1.0000
57.7400 96.0000 1.0000
57.8000 97.0000 1.0000
57.8600 94.0000 1.0000
57.9200 98.0000 1.0000
57.9800 104.0000 1.0000
58.0400 84.0000 1.0000
58.1000 99.0000 1.0000
58.1600 88.0000 1.0000
58.2200 89.0000 1.0000
58.2800 102.0000 1.0000
58.3400 92.0000 1.0000
58.4000 102.0000 1.0000
58.4600 101.0000 1.0000
58.5200 93.0000 1.0000
58.5800 99.0000 1.0000
58.6400 87.0000 1.0000
58.7000 91.0000 1.0000
58.7600 97.0000 1.0000
58.8200 99.0000 1.0000
58.8800 96.0000 1.0000
58.9400 94.0000 1.0000
59.0000 86.0000 1.0000
59.0600 103.0000 1.0000
59.1200 93.0000 1.0000
59.1800 92.0000 1.0000
59.2400 99.0000 1.0000
59.3000 90.0000 1.0000
59.3600 88.0000 1.0000
59.4200 102.0000 1.0000
59.4800 83.0000 1.0000
59.5400 94.0000 1.0000
59.6000 94.0000 1.0000
59.6600 103.0000 1.0000
59.7200 102.0000 1.0000
59.7800 118.0000 1.0000
59.8400 127.0000 1.0000
59.9000 133.0000 1.0000
59.9600 134.0000 1.0000
60.0200 128.0000 1.0000
60.0800 140.0000 1.0000
60.1400 125.0000 1.0000
60.2000 111.0000 1.0000
60.2600 104.0000 1.0000
60.3200 111.0000 1.0000
60.3800 97.0000 1.0000
60.4400 107.0000 1.0000
60.5000 94.0000 1.0000
60.5600 89.0000 1.0000
60.6200 89.0000 1.0000
60.6800 108.0000 1.0000
60.7400 97.0000 1.0000
60.8000 100.0000 1.0000
60.8600 99.0000 1.0000
60.9200 103.0000 1.0000
60.9800 96.0000 1.0000
61.0400 92.0000 1.0000
61.1000 87.0000 1.0000
61.1600 103.0000 1.0000
61.2200 105.0000 1.0000
61.2800 88.0000 1.0000
61.3400 108.0000 1.0000
61.4000 110.0000 1.0000
61.4600 98.0000 1.0000
61.5200 101.0000 1.0000
61.5800 105.0000 1.0000
61.6400 98.0000 1.0000
61.7000 100.0000 1.0000
61.7600 103.0000 1.0000
61.8200 101.0000 1.0000
61.8800 102.0000 1.0000
61.9400 102.0000 1.0000
62.0000 104.0000 1.0000
62.0600 99.0000 1.0000
62.1200 124.0000 1.0000
62.1800 122.0000 1.0000
62.2400 146.0000 1.0000
62.3000 171.0000 1.0000
62.3600 289.0000 1.0000
62.4200 509.0000 1.0000
62.4800 552.0000 1.0000
62.5400 412.0000 1.0000
62.6000 397.0000 1.0000
62.6600 377.0000 1.0000
62.7200 258.0000 1.0000
62.7800 201.0000 1.0000
62.8400 175.0000 1.0000
62.9000 140.0000 1.0000
62.9600 124.0000 1.0000
63.0200 124.0000 1.0000
63.0800 105.0000 1.0000
63.1400 118.0000 1.0000
63.2000 116.0000 1.0000
63.2600 118.0000 1.0000
63.3200 124.0000 1.0000
63.3800 135.0000 1.0000
63.4400 157.0000 1.0000
63.5000 188.0000 1.0000
63.5600 252.0000 1.0000
63.6200 333.0000 1.0000
63.6800 537.0000 1.0000
63.7400 602.0000 1.0000
63.8000 484.0000 1.0000
63.8600 456.0000 1.0000
63.9200 389.0000 1.0000
63.9800 277.0000 1.0000
64.0400 206.0000 1.0000
64.1000 180.0000 1.0000
64.1600 158.0000 1.0000
64.2200 141.0000 1.0000
64.2800 145.0000 1.0000
64.3400 145.0000 1.0000
64.4000 196.0000 1.0000
64.4600 313.0000 1.0000
64.5200 397.0000 1.0000
64.5800 290.0000 1.0000
64.6400 258.0000 1.0000
64.7000 276.0000 1.0000
64.7600 206.0000 1.0000
64.8200 154.0000 1.0000
64.8800 124.0000 1.0000
64.9400 117.0000 1.0000
65.0000 105.0000 1.0000
65.0600 100.0000 1.0000
65.1200 88.0000 1.0000
65.1800 108.0000 1.0000
65.2400 97.0000 1.0000
65.3000 102.0000 1.0000
65.3600 97.0000 1.0000
65.4200 98.0000 1.0000
65.4800 92.0000 1.0000
65.5400 87.0000 1.0000
65.6000 90.0000 1.0000
65.6600 101.0000 1.0000
65.7200 94.0000 1.0000
65.7800 94.0000 1.0000
65.8400 85.0000 1.0000
65.9000 91.0000 1.0000
65.9600 91.0000 1.0000
66.0200 94.0000 1.0000
66.0800 97.0000 1.0000
66.1400 100.0000 1.0000
66.2000 89.0000 1.0000
66.2600 108.0000 1.0000
66.3200 96.0000 1.0000
66.3800 94.0000 1.0000
66.4400 94.0000 1.0000
66.5000 94.0000 1.0000
66.5600 93.0000 1.0000
66.6200 99.0000 1.0000
66.6800 90.0000 1.0000
66.7400 88.0000 1.0000
66.8000 94.0000 1.0000
66.8600 95.0000 1.0000
66.9200 92.0000 1.0000
66.9800 89.0000 1.0000
67.0400 83.0000 1.0000
67.1000 93.0000 1.0000
67.1600 84.0000 1.0000
67.2200 88.0000 1.0000
67.2800 88.0000 1.0000
67.3400 96.0000 1.0000
67.4000 100.0000 1.0000
67.4600 93.0000 1.0000
67.5200 92.0000 1.0000
67.5800 91.0000 1.0000
67.6400 90.0000 1.0000
67.7000 96.0000 1.0000
67.7600 88.0000 1.0000
67.8200 93.0000 1.0000
67.8800 94.0000 1.0000
67.9400 96.0000 1.0000
68.0000 93.0000 1.0000
68.0600 80.0000 1.0000
68.1200 94.0000 1.0000
68.1800 80.0000 1.0000
68.2400 91.0000 1.0000
68.3000 92.0000 1.0000
68.3600 102.0000 1.0000
68.4200 103.0000 1.0000
68.4800 80.0000 1.0000
68.5400 93.0000 1.0000
68.6000 89.0000 1.0000
68.6600 83.0000 1.0000
68.7200 101.0000 1.0000
68.7800 91.0000 1.0000
68.8400 95.0000 1.0000
68.9000 110.0000 1.0000
68.9600 101.0000 1.0000
69.0200 91.0000 1.0000
69.0800 96.0000 1.0000
69.1400 92.0000 1.0000
69.2000 93.0000 1.0000
69.2600 99.0000 1.0000
69.3200 92.0000 1.0000
69.3800 93.0000 1.0000
69.4400 92.0000 1.0000
69.5000 97.0000 1.0000
69.5600 99.0000 1.0000
69.6200 96.0000 1.0000
69.6800 92.0000 1.0000
69.7400 94.0000 1.0000
69.8000 92.0000 1.0000
69.8600 100.0000 1.0000
69.9200 86.0000 1.0000
69.9800 93.0000 1.0000
70.0400 89.0000 1.0000
70.1000 96.0000 1.0000
70.1600 95.0000 1.0000
70.2200 104.0000 1.0000
70.2800 107.0000 1.0000
70.3400 98.0000 1.0000
70.4000 106.0000 1.0000
70.4600 109.0000 1.0000
70.5200 116.0000 1.0000
70.5800 121.0000 1.0000
70.6400 149.0000 1.0000
70.7000 151.0000 1.0000
70.7600 150.0000 1.0000
70.8200 155.0000 1.0000
70.8800 140.0000 1.0000
70.9400 154.0000 1.0000
71.0000 128.0000 1.0000
71.0600 128.0000 1.0000
71.1200 115.0000 1.0000
71.1800 100.0000 1.0000
71.2400 110.0000 1.0000
71.3000 99.0000 1.0000
71.3600 104.0000 1.0000
71.4200 103.0000 1.0000
71.4800 104.0000 1.0000
71.5400 89.0000 1.0000
71.6000 92.0000 1.0000
71.6600 88.0000 1.0000
71.7200 105.0000 1.0000
71.7800 111.0000 1.0000
71.8400 104.0000 1.0000
71.9000 98.0000 1.0000
71.9600 111.0000 1.0000
72.0200 94.0000 1.0000
72.0800 106.0000 1.0000
72.1400 116.0000 1.0000
72.2000 131.0000 1.0000
72.2600 150.0000 1.0000
72.3200 231.0000 1.0000
72.3800 223.0000 1.0000
72.4400 187.0000 1.0000
72.5000 177.0000 1.0000
72.5600 178.0000 1.0000
72.6200 152.0000 1.0000
72.6800 129.0000 1.0000
72.7400 128.0000 1.0000
72.8000 119.0000 1.0000
72.8600 119.0000 1.0000
72.9200 135.0000 1.0000
72.9800 161.0000 1.0000
73.0400 224.0000 1.0000
73.1000 249.0000 1.0000
73.1600 221.0000 1.0000
73.2200 179.0000 1.0000
73.2800 179.0000 1.0000
73.3400 171.0000 1.0000
73.4000 137.0000 1.0000
73.4600 111.0000 1.0000
73.5200 116.0000 1.0000
73.5800 95.0000 1.0000
73.6400 104.0000 1.0000
73.7000 91.0000 1.0000
73.7600 90.0000 1.0000
73.8200 88.0000 1.0000
73.8800 96.0000 1.0000
73.9400 93.0000 1.0000
74.0000 95.0000 1.0000
74.0600 84.0000 1.0000
74.1200 88.0000 1.0000
74.1800 107.0000 1.0000
74.2400 108.0000 1.0000
74.3000 99.0000 1.0000
74.3600 90.0000 1.0000
74.4200 100.0000 1.0000
74.4800 96.0000 1.0000
74.5400 89.0000 1.0000
74.6000 89.0000 1.0000
74.6600 98.0000 1.0000
74.7200 94.0000 1.0000
74.7800 99.0000 1.0000
74.8400 99.0000 1.0000
74.9000 79.0000 1.0000
74.9600 87.0000 1.0000
75.0200 94.0000 1.0000
75.0800 91.0000 1.0000
75.1400 86.0000 1.0000
75.2000 81.0000 1.0000
75.2600 96.0000 1.0000
75.3200 85.0000 1.0000
75.3800 85.0000 1.0000
75.4400 101.0000 1.0000
75.5000 93.0000 1.0000
75.5600 77.0000 1.0000
75.6200 78.0000 1.0000
75.6800 98.0000 1.0000
75.7400 87.0000 1.0000
75.8000 85.0000 1.0000
75.8600 83.0000 1.0000
75.9200 85.0000 1.0000
75.9800 90.0000 1.0000
76.0400 82.0000 1.0000
76.1000 77.0000 1.0000
76.1600 91.0000 1.0000
76.2200 97.0000 1.0000
76.2800 84.0000 1.0000
76.3400 87.0000 1.0000
76.4000 97.0000 1.0000
76.4600 97.0000 1.0000
76.5200 102.0000 1.0000
76.5800 104.0000 1.0000
76.6400 117.0000 1.0000
76.7000 107.0000 1.0000
76.7600 95.0000 1.0000
76.8200 111.0000 1.0000
76.8800 100.0000 1.0000
76.9400 87.0000 1.0000
77.0000 93.0000 1.0000
77.0600 89.0000 1.0000
77.1200 92.0000 1.0000
77.1800 86.0000 1.0000
77.2400 81.0000 1.0000
77.3000 96.0000 1.0000
77.3600 86.0000 1.0000
77.4200 84.0000 1.0000
77.4800 76.0000 1.0000
77.5400 73.0000 1.0000
77.6000 84.0000 1.0000
77.6600 77.0000 1.0000
77.7200 78.0000 1.0000
77.7800 89.0000 1.0000
77.8400 87.0000 1.0000
77.9000 92.0000 1.0000
77.9600 91.0000 1.0000
78.0200 84.0000 1.0000
78.0800 80.0000 1.0000
78.1400 74.0000 1.0000
78.2000 88.0000 1.0000
78.2600 92.0000 1.0000
78.3200 88.0000 1.0000
78.3800 92.0000 1.0000
78.4400 106.0000 1.0000
78.5000 119.0000 1.0000
78.5600 152.0000 1.0000
78.6200 154.0000 1.0000
78.6800 156.0000 1.0000
78.7400 170.0000 1.0000
78.8000 176.0000 1.0000
78.8600 184.0000 1.0000
78.9200 189.0000 1.0000
78.9800 169.0000 1.0000
79.0400 162.0000 1.0000
79.1000 137.0000 1.0000
79.1600 139.0000 1.0000
79.2200 142.0000 1.0000
79.2800 170.0000 1.0000
79.3400 228.0000 1.0000
79.4000 327.0000 1.0000
79.4600 376.0000 1.0000
79.5200 249.0000 1.0000
79.5800 203.0000 1.0000
79.6400 204.0000 1.0000
79.7000 207.0000 1.0000
79.7600 157.0000 1.0000
79.8200 119.0000 1.0000
79.8800 99.0000 1.0000
79.9400 99.0000 1.0000
80.0000 95.0000 1.0000
80.0600 90.0000 1.0000
80.1200 91.0000 1.0000
80.1800 83.0000 1.0000
80.2400 88.0000 1.0000
80.3000 84.0000 1.0000
80.3600 66.0000 1.0000
80.4200 78.0000 1.0000
80.4800 79.0000 1.0000
80.5400 69.0000 1.0000
80.6000 87.0000 1.0000
80.6600 77.0000 1.0000
80.7200 75.0000 1.0000
80.7800 81.0000 1.0000
80.8400 73.0000 1.0000
80.9000 77.0000 1.0000
80.9600 78.0000 1.0000
81.0200 83.0000 1.0000
81.0800 88.0000 1.0000
81.1400 75.0000 1.0000
81.2000 82.0000 1.0000
81.2600 74.0000 1.0000
81.3200 81.0000 1.0000
81.3800 82.0000 1.0000
81.4400 81.0000 1.0000
81.5000 74.0000 1.0000
81.5600 75.0000 1.0000
81.6200 78.0000 1.0000
81.6800 77.0000 1.0000
81.7400 76.0000 1.0000
81.8000 71.0000 1.0000
81.8600 87.0000 1.0000
81.9200 91.0000 1.0000
81.9800 72.0000 1.0000
82.0400 81.0000 1.0000
82.1000 79.0000 1.0000
82.1600 82.0000 1.0000
82.2200 78.0000 1.0000
82.2800 75.0000 1.0000
82.3400 75.0000 1.0000
82.4000 81.0000 1.0000
82.4600 65.0000 1.0000
82.5200 80.0000 1.0000
82.5800 67.0000 1.0000
82.6400 93.0000 1.0000
82.7000 78.0000 1.0000
82.7600 78.0000 1.0000
82.8200 84.0000 1.0000
82.8800 79.0000 1.0000
82.9400 70.0000 1.0000
83.0000 83.0000 1.0000
83.0600 80.0000 1.0000
83.1200 87.0000 1.0000
83.1800 81.0000 1.0000
83.2400 82.0000 1.0000
83.3000 69.0000 1.0000
83.3600 79.0000 1.0000
83.4200 89.0000 1.0000
83.4800 69.0000 1.0000
83.5400 90.0000 1.0000
83.6000 68.0000 1.0000
83.6600 72.0000 1.0000
83.7200 79.0000 1.0000
83.7800 70.0000 1.0000
83.8400 72.0000 1.0000
83.9000 80.0000 1.0000
83.9600 77.0000 1.0000
84.0200 81.0000 1.0000
84.0800 84.0000 1.0000
84.1400 77.0000 1.0000
84.2000 80.0000 1.0000
84.2600 69.0000 1.0000
84.3200 69.0000 1.0000
84.3800 71.0000 1.0000
84.4400 68.0000 1.0000
84.5000 72.0000 1.0000
84.5600 80.0000 1.0000
84.6200 68.0000 1.0000
84.6800 76.0000 1.0000
84.7400 76.0000 1.0000
84.8000 78.0000 1.0000
84.8600 83.0000 1.0000
84.9200 68.0000 1.0000
84.9800 77.0000 1.0000
85.0400 75.0000 1.0000
85.1000 76.0000 1.0000
85.1600 73.0000 1.0000
85.2200 78.0000 1.0000
85.2800 92.0000 1.0000
85.3400 81.0000 1.0000
85.4000 80.0000 1.0000
85.4600 61.0000 1.0000
85.5200 77.0000 1.0000
85.5800 83.0000 1.0000
85.6400 86.0000 1.0000
85.7000 77.0000 1.0000
85.7600 65.0000 1.0000
85.8200 76.0000 1.0000
85.8800 73.0000 1.0000
85.9400 80.0000 1.0000
86.0000 68.0000 1.0000
86.0600 71.0000 1.0000
86.1200 67.0000 1.0000
86.1800 68.0000 1.0000
86.2400 70.0000 1.0000
86.3000 78.0000 1.0000
86.3600 84.0000 1.0000
86.4200 81.0000 1.0000
86.4800 70.0000 1.0000
86.5400 79.0000 1.0000
86.6000 73.0000 1.0000
86.6600 67.0000 1.0000
86.7200 79.0000 1.0000
86.7800 84.0000 1.0000
86.8400 76.0000 1.0000
86.9000 78.0000 1.0000
86.9600 92.0000 1.0000
87.0200 79.0000 1.0000
87.0800 89.0000 1.0000
87.1400 80.0000 1.0000
87.2000 82.0000 1.0000
87.2600 66.0000 1.0000
87.3200 72.0000 1.0000
87.3800 75.0000 1.0000
87.4400 76.0000 1.0000
87.5000 75.0000 1.0000
87.5600 83.0000 1.0000
87.6200 74.0000 1.0000
87.6800 75.0000 1.0000
87.7400 79.0000 1.0000
87.8000 83.0000 1.0000
87.8600 70.0000 1.0000
87.9200 75.0000 1.0000
87.9800 78.0000 1.0000
88.0400 77.0000 1.0000
88.1000 75.0000 1.0000
88.1600 80.0000 1.0000
88.2200 65.0000 1.0000
88.2800 68.0000 1.0000
88.3400 74.0000 1.0000
88.4000 67.0000 1.0000
88.4600 86.0000 1.0000
88.5200 80.0000 1.0000
88.5800 76.0000 1.0000
88.6400 76.0000 1.0000
88.7000 82.0000 1.0000
88.7600 87.0000 1.0000
88.8200 81.0000 1.0000
88.8800 88.0000 1.0000
88.9400 93.0000 1.0000
89.0000 90.0000 1.0000
89.0600 90.0000 1.0000
89.1200 104.0000 1.0000
89.1800 109.0000 1.0000
89.2400 134.0000 1.0000
89.3000 204.0000 1.0000
89.3600 207.0000 1.0000
89.4200 182.0000 1.0000
89.4800 148.0000 1.0000
89.5400 161.0000 1.0000
89.6000 165.0000 1.0000
89.6600 170.0000 1.0000
89.7200 147.0000 1.0000
89.7800 121.0000 1.0000
89.8400 137.0000 1.0000
89.9000 120.0000 1.0000
89.9600 120.0000 1.0000
90.0000 125.0000 1.0000
*RAS_INT_END
*RAS_DATA_END