File: xrd_umap_package_ja/data/cu-75%sn.500rpm-1-1451-1_1.ras
*RAS_DATA_START
*RAS_HEADER_START
*CORR_POS_DB_NAME "Dtex_20210428"
*CORR_POS_GONIO_RADIUS ""
*CORR_POS_NODE_INDEX01 ""
*CORR_POS_NODE_INDEX02 ""
*CORR_POS_NODE_INDEX03 ""
*CORR_POS_NODE_INDEX04 ""
*CORR_POS_NODE_INDEX05 ""
*CORR_POS_NODE_INDEX06 ""
*CORR_POS_NODE_INDEX07 ""
*CORR_POS_NODE_INDEX08 ""
*CORR_POS_NODE_INDEX09 ""
*CORR_POS_NODE_INDEX10 ""
*CORR_POS_NODE_INDEX11 ""
*CORR_POS_NODE_LABEL01 "Si(111)"
*CORR_POS_NODE_LABEL02 "Si(220)"
*CORR_POS_NODE_LABEL03 "Si(311)"
*CORR_POS_NODE_LABEL04 "Si(400)"
*CORR_POS_NODE_LABEL05 "Si(331)"
*CORR_POS_NODE_LABEL06 "Si(422)"
*CORR_POS_NODE_LABEL07 "Si(511)"
*CORR_POS_NODE_LABEL08 "Si(440)"
*CORR_POS_NODE_LABEL09 "Si(531)"
*CORR_POS_NODE_LABEL10 "Si(620)"
*CORR_POS_NODE_LABEL11 "Si(533)"
*CORR_POS_NODE_POS_CALC01 "28.3773"
*CORR_POS_NODE_POS_CALC02 "47.2511"
*CORR_POS_NODE_POS_CALC03 "56.073"
*CORR_POS_NODE_POS_CALC04 "69.0829"
*CORR_POS_NODE_POS_CALC05 "76.3303"
*CORR_POS_NODE_POS_CALC06 "87.9864"
*CORR_POS_NODE_POS_CALC07 "94.9103"
*CORR_POS_NODE_POS_CALC08 "106.67"
*CORR_POS_NODE_POS_CALC09 "114.056"
*CORR_POS_NODE_POS_CALC10 "127.514"
*CORR_POS_NODE_POS_CALC11 "136.867"
*CORR_POS_NODE_POS_MEAS01 "28.4014"
*CORR_POS_NODE_POS_MEAS02 "47.2553"
*CORR_POS_NODE_POS_MEAS03 "56.0727"
*CORR_POS_NODE_POS_MEAS04 "69.0771"
*CORR_POS_NODE_POS_MEAS05 "76.3223"
*CORR_POS_NODE_POS_MEAS06 "87.9752"
*CORR_POS_NODE_POS_MEAS07 "94.897"
*CORR_POS_NODE_POS_MEAS08 "106.653"
*CORR_POS_NODE_POS_MEAS09 "114.038"
*CORR_POS_NODE_POS_MEAS10 "127.488"
*CORR_POS_NODE_POS_MEAS11 "136.841"
*CORR_POS_OPT_ATTR "集中法"
*CORR_POS_PARAM_MU ""
*CORR_POS_PARAM_PL ""
*CORR_POS_SEMODEL_TYPE "0"
*CORR_POS_STANDARD_TYPE ""
*CORR_POS_VALUE_ANALYZER "None"
*CORR_POS_VALUE_CMONO "None_None"
*CORR_POS_VALUE_IMONO "None"
*CORR_POS_VALUE_IS "1.250deg"
*CORR_POS_VALUE_ISL "10.0mm"
*CORR_POS_VALUE_ISOLLER "5.0deg"
*CORR_POS_VALUE_RS1 "13.0mm"
*CORR_POS_VALUE_RS2 "13.0mm"
*CORR_POS_VALUE_RSOLLER "5.0deg"
*CORR_POS_XG_FOCUS_L ""
*CORR_POS_XG_WAVE_TYPE ""
*CORR_POS_XG_WAVE_VALUE ""
*DISP_FMT_X "%.2f"
*DISP_FMT_Y "%.0f"
*DISP_FULLSCALE "162880.0000000000"
*DISP_LINE_COLOR "255.0000000000"
*DISP_LINE_STYLE "0.0000000000"
*DISP_LINE_WIDTH "0.2500000000"
*DISP_NOTE "測定データ-1"
*DISP_OFFSET_Y "0.0000000000"
*DISP_PEAKSEARCH_UNIT_Y "cps"
*DISP_RANGE_BOTTOM "0.0000000000"
*DISP_RANGE_LEFT "5.0000000000"
*DISP_RANGE_LOGCUTOFF "0.0100000000"
*DISP_RANGE_RIGHT "90.0000000000"
*DISP_RANGE_TOP "162880.0000000000"
*DISP_SCALE_MODE_Y "0.0000000000"
*DISP_TAB_NAME "2θ/θ"
*DISP_TITLE_Y "強度"
*DISP_UNIT_Y "cps"
*DISP_WINDOW_NAME "MSG_MACROENGINE"
*FILE_COMMENT " "
*FILE_MD5 ""
*FILE_MEMO " "
*FILE_OPERATOR "administrator"
*FILE_PART_ID "MEAS_PBEA_00223"
*FILE_SAMPLE "cu-75%sn.500rpm"
*FILE_TYPE "RAS_RAW"
*FILE_USERGROUP "システムマネージャ"
*FILE_VERSION "1.0000000000"
*HW_ATTACHMENT_ID "ATT1025"
*HW_ATTACHMENT_NAME "標準試料台|Standard Sample Stage"
*HW_COUNTER_ID-0 "CUT0025"
*HW_COUNTER_ID-1 "CUT0020"
*HW_COUNTER_ID-2 "CUT0020"
*HW_COUNTER_ID-3 "CMC0021"
*HW_COUNTER_NAME-0 "D/teX Ultra2|D/teX Ultra2"
*HW_COUNTER_NAME-1 "None|None"
*HW_COUNTER_NAME-2 "None|None"
*HW_COUNTER_NAME-3 "検出器モノクロメータ|Detector monochromator"
*HW_COUNTER_SELECT_NAME "D/teX Ultra2|D/teX Ultra2"
*HW_GONIOMETER_ID "GON0070"
*HW_GONIOMETER_NAME "MiniFlex 300/600|MiniFlex 300/600"
*HW_GONIOMETER_RADIUS-0 "79.0"
*HW_GONIOMETER_RADIUS-1 "91.5"
*HW_GONIOMETER_RADIUS-2 "150.0"
*HW_GONIOMETER_RADIUS-3 "0"
*HW_GONIOMETER_RADIUS-4 "92.7"
*HW_GONIOMETER_RADIUS-5 "139.3"
*HW_GONIOMETER_RADIUS-6 "46.6"
*HW_GONIOMETER_RADIUS-7 "150.0"
*HW_I_OPT_ID-0 "ISL0021"
*HW_I_OPT_ID-1 "ISO0021"
*HW_I_OPT_NAME-0 "発散スリット|Divergence slit"
*HW_I_OPT_NAME-1 "入射平行スリット|Incident parallel slit"
*HW_R_ATTENUATER_AUTOMODE "0"
*HW_R_OPT_ID-0 "RSS0021"
*HW_R_OPT_ID-1 "RSO0021"
*HW_R_OPT_ID-2 "RRS0021"
*HW_R_OPT_NAME-0 "散乱スリット|Scattering slit"
*HW_R_OPT_NAME-1 "受光平行スリット|Receiving soller slit"
*HW_R_OPT_NAME-2 "受光スリット|Receiving slit"
*HW_SAMPLE_HOLDER_ID "SMP0000"
*HW_SAMPLE_HOLDER_NAME "無し|None"
*HW_XG_CURRENT_MAX "15"
*HW_XG_CURRENT_MIN "2"
*HW_XG_CURRENT_RESOLUTION "1"
*HW_XG_CURRENT_UNIT "mA"
*HW_XG_FOCUS "1mm x 10mm"
*HW_XG_FOCUS_TYPE "Normal"
*HW_XG_ID "1060"
*HW_XG_NAME "300W/600W 封入管-B|300W/600W Sealed tube-B"
*HW_XG_TARGET_ATOMIC_NUMBER "29.0000000000"
*HW_XG_TARGET_NAME "Cu"
*HW_XG_TYPE "Hermetic"
*HW_XG_VOLTAGE_MAX "40"
*HW_XG_VOLTAGE_MIN "20"
*HW_XG_VOLTAGE_RESOLUTION "1"
*HW_XG_VOLTAGE_UNIT "kV"
*HW_XG_WATT_MAX "1"
*HW_XG_WATT_UNIT "kW"
*HW_XG_WAVE_LENGTH_ALPHA1 "1.540593"
*HW_XG_WAVE_LENGTH_ALPHA2 "1.544414"
*HW_XG_WAVE_LENGTH_BETA "1.392250"
*MEAS_COND_AXIS_NAME-0 "2θ/θ"
*MEAS_COND_AXIS_NAME-1 "Soller(inc.)"
*MEAS_COND_AXIS_NAME-2 "IHS"
*MEAS_COND_AXIS_NAME-3 "DS"
*MEAS_COND_AXIS_NAME-4 "SS"
*MEAS_COND_AXIS_NAME-5 "Soller(rec.)"
*MEAS_COND_AXIS_NAME-6 "RS"
*MEAS_COND_AXIS_NAME-7 "フィルター"
*MEAS_COND_AXIS_NAME-8 "モノクロメータ"
*MEAS_COND_AXIS_NAME-9 "PHA"
*MEAS_COND_AXIS_NAME_INTERNAL-0 "TwoThetaTheta"
*MEAS_COND_AXIS_NAME_INTERNAL-1 "IncidentSollerSlit"
*MEAS_COND_AXIS_NAME_INTERNAL-2 "IncidentAxdSlit"
*MEAS_COND_AXIS_NAME_INTERNAL-3 "IncidentSlitBox"
*MEAS_COND_AXIS_NAME_INTERNAL-4 "ReceivingSlitBox1"
*MEAS_COND_AXIS_NAME_INTERNAL-5 "ReceivingSollerSlit"
*MEAS_COND_AXIS_NAME_INTERNAL-6 "ReceivingSlitBox2"
*MEAS_COND_AXIS_NAME_INTERNAL-7 "Filter"
*MEAS_COND_AXIS_NAME_INTERNAL-8 "CounterMonochromator"
*MEAS_COND_AXIS_NAME_INTERNAL-9 "PHA"
*MEAS_COND_AXIS_NAME_MAGICNO-0 "268632064.0000000000"
*MEAS_COND_AXIS_NAME_MAGICNO-1 "20971521.0000000000"
*MEAS_COND_AXIS_NAME_MAGICNO-2 "22020097.0000000000"
*MEAS_COND_AXIS_NAME_MAGICNO-3 "22020097.0000000000"
*MEAS_COND_AXIS_NAME_MAGICNO-4 "23068673.0000000000"
*MEAS_COND_AXIS_NAME_MAGICNO-5 "20971521.0000000000"
*MEAS_COND_AXIS_NAME_MAGICNO-6 "23068673.0000000000"
*MEAS_COND_AXIS_NAME_MAGICNO-7 "20971521.0000000000"
*MEAS_COND_AXIS_NAME_MAGICNO-8 "20971521.0000000000"
*MEAS_COND_AXIS_NAME_MAGICNO-9 "0.0000000000"
*MEAS_COND_AXIS_OFFSET-0 "0.0000000000"
*MEAS_COND_AXIS_OFFSET-1 "-"
*MEAS_COND_AXIS_OFFSET-2 "-"
*MEAS_COND_AXIS_OFFSET-3 "-"
*MEAS_COND_AXIS_OFFSET-4 "-"
*MEAS_COND_AXIS_OFFSET-5 "-"
*MEAS_COND_AXIS_OFFSET-6 "-"
*MEAS_COND_AXIS_OFFSET-7 "-"
*MEAS_COND_AXIS_OFFSET-8 "-"
*MEAS_COND_AXIS_OFFSET-9 "-"
*MEAS_COND_AXIS_POSITION-0 "12.0000000000"
*MEAS_COND_AXIS_POSITION-1 "5.0deg"
*MEAS_COND_AXIS_POSITION-2 "10.0mm"
*MEAS_COND_AXIS_POSITION-3 "1.250deg"
*MEAS_COND_AXIS_POSITION-4 "8.0mm"
*MEAS_COND_AXIS_POSITION-5 "5.0deg"
*MEAS_COND_AXIS_POSITION-6 "13.0mm(Open)"
*MEAS_COND_AXIS_POSITION-7 "K-beta(x2)"
*MEAS_COND_AXIS_POSITION-8 "None"
*MEAS_COND_AXIS_POSITION-9 "48.0000000000"
*MEAS_COND_AXIS_UNIT-0 "deg"
*MEAS_COND_AXIS_UNIT-1 ""
*MEAS_COND_AXIS_UNIT-2 ""
*MEAS_COND_AXIS_UNIT-3 ""
*MEAS_COND_AXIS_UNIT-4 ""
*MEAS_COND_AXIS_UNIT-5 ""
*MEAS_COND_AXIS_UNIT-6 ""
*MEAS_COND_AXIS_UNIT-7 ""
*MEAS_COND_AXIS_UNIT-8 ""
*MEAS_COND_AXIS_UNIT-9 "div"
*MEAS_COND_COUNTER_CNTLOSS_CORR "0.0000000000"
*MEAS_COND_COUNTER_PHABASE "48.0000000000"
*MEAS_COND_COUNTER_PHAWINDOW "9.0000000000"
*MEAS_COND_COUNTER_PHA_UNIT "div"
*MEAS_COND_COUNTER_TAUDIFF "0.2500000000"
*MEAS_COND_COUNTER_TAUINT "0.7500000000"
*MEAS_COND_IRRADIATION_MODE "OFF"
*MEAS_COND_IRRADIATION_WIDTH ""
*MEAS_COND_OPT_ATTR " "
*MEAS_COND_OPT_NAME ""
*MEAS_COND_UNSYMMETRIC_MODE "OFF"
*MEAS_COND_XG_CURRENT "15.0000000000"
*MEAS_COND_XG_VOLTAGE "40.0000000000"
*MEAS_COND_XG_WAVE_TYPE "Ka"
*MEAS_DATA_COUNT "8501.0000000000"
*MEAS_SCAN_AXIS_X "2θ/θ"
*MEAS_SCAN_AXIS_X_INTERNAL "TwoThetaTheta"
*MEAS_SCAN_END_TIME "04/09/24 14:56:21"
*MEAS_SCAN_MODE "CONTINUOUS"
*MEAS_SCAN_MONITOR "0"
*MEAS_SCAN_RESOLUTION_X "0.0025"
*MEAS_SCAN_SPEED "20.000000"
*MEAS_SCAN_SPEED_UNIT "deg/min"
*MEAS_SCAN_SPEED_USER "20.000000"
*MEAS_SCAN_START "5.0000000000"
*MEAS_SCAN_START_TIME "04/09/24 14:51:33"
*MEAS_SCAN_STEP "0.0100000000"
*MEAS_SCAN_STOP "90.0000000000"
*MEAS_SCAN_UNIT_X "deg"
*MEAS_SCAN_UNIT_Y "counts"
*SLIT_SYSTEM "0"
*RAS_HEADER_END
*RAS_INT_START
5.0000 228.0000 1.0000
5.0600 239.0000 1.0000
5.1200 221.0000 1.0000
5.1800 230.0000 1.0000
5.2400 235.0000 1.0000
5.3000 222.0000 1.0000
5.3600 222.0000 1.0000
5.4200 211.0000 1.0000
5.4800 215.0000 1.0000
5.5400 213.0000 1.0000
5.6000 234.0000 1.0000
5.6600 229.0000 1.0000
5.7200 223.0000 1.0000
5.7800 237.0000 1.0000
5.8400 230.0000 1.0000
5.9000 241.0000 1.0000
5.9600 227.0000 1.0000
6.0200 227.0000 1.0000
6.0800 223.0000 1.0000
6.1400 226.0000 1.0000
6.2000 221.0000 1.0000
6.2600 215.0000 1.0000
6.3200 227.0000 1.0000
6.3800 218.0000 1.0000
6.4400 225.0000 1.0000
6.5000 219.0000 1.0000
6.5600 218.0000 1.0000
6.6200 227.0000 1.0000
6.6800 228.0000 1.0000
6.7400 225.0000 1.0000
6.8000 228.0000 1.0000
6.8600 232.0000 1.0000
6.9200 242.0000 1.0000
6.9800 234.0000 1.0000
7.0400 234.0000 1.0000
7.1000 229.0000 1.0000
7.1600 245.0000 1.0000
7.2200 232.0000 1.0000
7.2800 256.0000 1.0000
7.3400 241.0000 1.0000
7.4000 237.0000 1.0000
7.4600 223.0000 1.0000
7.5200 223.0000 1.0000
7.5800 238.0000 1.0000
7.6400 248.0000 1.0000
7.7000 232.0000 1.0000
7.7600 251.0000 1.0000
7.8200 231.0000 1.0000
7.8800 259.0000 1.0000
7.9400 235.0000 1.0000
8.0000 236.0000 1.0000
8.0600 263.0000 1.0000
8.1200 257.0000 1.0000
8.1800 261.0000 1.0000
8.2400 249.0000 1.0000
8.3000 248.0000 1.0000
8.3600 237.0000 1.0000
8.4200 245.0000 1.0000
8.4800 236.0000 1.0000
8.5400 257.0000 1.0000
8.6000 251.0000 1.0000
8.6600 254.0000 1.0000
8.7200 261.0000 1.0000
8.7800 254.0000 1.0000
8.8400 268.0000 1.0000
8.9000 257.0000 1.0000
8.9600 252.0000 1.0000
9.0200 241.0000 1.0000
9.0800 274.0000 1.0000
9.1400 264.0000 1.0000
9.2000 249.0000 1.0000
9.2600 260.0000 1.0000
9.3200 255.0000 1.0000
9.3800 264.0000 1.0000
9.4400 272.0000 1.0000
9.5000 248.0000 1.0000
9.5600 270.0000 1.0000
9.6200 264.0000 1.0000
9.6800 274.0000 1.0000
9.7400 273.0000 1.0000
9.8000 276.0000 1.0000
9.8600 282.0000 1.0000
9.9200 276.0000 1.0000
9.9800 259.0000 1.0000
10.0400 264.0000 1.0000
10.1000 282.0000 1.0000
10.1600 274.0000 1.0000
10.2200 298.0000 1.0000
10.2800 280.0000 1.0000
10.3400 263.0000 1.0000
10.4000 256.0000 1.0000
10.4600 287.0000 1.0000
10.5200 301.0000 1.0000
10.5800 301.0000 1.0000
10.6400 283.0000 1.0000
10.7000 281.0000 1.0000
10.7600 276.0000 1.0000
10.8200 270.0000 1.0000
10.8800 283.0000 1.0000
10.9400 298.0000 1.0000
11.0000 279.0000 1.0000
11.0600 271.0000 1.0000
11.1200 294.0000 1.0000
11.1800 310.0000 1.0000
11.2400 269.0000 1.0000
11.3000 282.0000 1.0000
11.3600 289.0000 1.0000
11.4200 297.0000 1.0000
11.4800 293.0000 1.0000
11.5400 300.0000 1.0000
11.6000 303.0000 1.0000
11.6600 264.0000 1.0000
11.7200 280.0000 1.0000
11.7800 295.0000 1.0000
11.8400 306.0000 1.0000
11.9000 303.0000 1.0000
11.9600 298.0000 1.0000
12.0200 297.0000 1.0000
12.0800 281.0000 1.0000
12.1400 296.0000 1.0000
12.2000 284.0000 1.0000
12.2600 285.0000 1.0000
12.3200 316.0000 1.0000
12.3800 308.0000 1.0000
12.4400 304.0000 1.0000
12.5000 308.0000 1.0000
12.5600 299.0000 1.0000
12.6200 312.0000 1.0000
12.6800 309.0000 1.0000
12.7400 316.0000 1.0000
12.8000 292.0000 1.0000
12.8600 334.0000 1.0000
12.9200 305.0000 1.0000
12.9800 325.0000 1.0000
13.0400 306.0000 1.0000
13.1000 321.0000 1.0000
13.1600 309.0000 1.0000
13.2200 318.0000 1.0000
13.2800 329.0000 1.0000
13.3400 298.0000 1.0000
13.4000 330.0000 1.0000
13.4600 303.0000 1.0000
13.5200 331.0000 1.0000
13.5800 306.0000 1.0000
13.6400 327.0000 1.0000
13.7000 296.0000 1.0000
13.7600 288.0000 1.0000
13.8200 303.0000 1.0000
13.8800 309.0000 1.0000
13.9400 291.0000 1.0000
14.0000 315.0000 1.0000
14.0600 289.0000 1.0000
14.1200 320.0000 1.0000
14.1800 309.0000 1.0000
14.2400 277.0000 1.0000
14.3000 276.0000 1.0000
14.3600 311.0000 1.0000
14.4200 283.0000 1.0000
14.4800 306.0000 1.0000
14.5400 278.0000 1.0000
14.6000 287.0000 1.0000
14.6600 313.0000 1.0000
14.7200 299.0000 1.0000
14.7800 305.0000 1.0000
14.8400 291.0000 1.0000
14.9000 294.0000 1.0000
14.9600 295.0000 1.0000
15.0200 311.0000 1.0000
15.0800 279.0000 1.0000
15.1400 295.0000 1.0000
15.2000 310.0000 1.0000
15.2600 294.0000 1.0000
15.3200 295.0000 1.0000
15.3800 287.0000 1.0000
15.4400 301.0000 1.0000
15.5000 286.0000 1.0000
15.5600 291.0000 1.0000
15.6200 295.0000 1.0000
15.6800 276.0000 1.0000
15.7400 312.0000 1.0000
15.8000 297.0000 1.0000
15.8600 313.0000 1.0000
15.9200 259.0000 1.0000
15.9800 291.0000 1.0000
16.0400 284.0000 1.0000
16.1000 273.0000 1.0000
16.1600 296.0000 1.0000
16.2200 290.0000 1.0000
16.2800 283.0000 1.0000
16.3400 278.0000 1.0000
16.4000 276.0000 1.0000
16.4600 286.0000 1.0000
16.5200 261.0000 1.0000
16.5800 270.0000 1.0000
16.6400 267.0000 1.0000
16.7000 295.0000 1.0000
16.7600 302.0000 1.0000
16.8200 281.0000 1.0000
16.8800 282.0000 1.0000
16.9400 265.0000 1.0000
17.0000 276.0000 1.0000
17.0600 285.0000 1.0000
17.1200 286.0000 1.0000
17.1800 307.0000 1.0000
17.2400 279.0000 1.0000
17.3000 281.0000 1.0000
17.3600 282.0000 1.0000
17.4200 262.0000 1.0000
17.4800 272.0000 1.0000
17.5400 271.0000 1.0000
17.6000 272.0000 1.0000
17.6600 282.0000 1.0000
17.7200 288.0000 1.0000
17.7800 258.0000 1.0000
17.8400 263.0000 1.0000
17.9000 269.0000 1.0000
17.9600 276.0000 1.0000
18.0200 272.0000 1.0000
18.0800 272.0000 1.0000
18.1400 273.0000 1.0000
18.2000 257.0000 1.0000
18.2600 276.0000 1.0000
18.3200 272.0000 1.0000
18.3800 269.0000 1.0000
18.4400 272.0000 1.0000
18.5000 280.0000 1.0000
18.5600 270.0000 1.0000
18.6200 244.0000 1.0000
18.6800 246.0000 1.0000
18.7400 262.0000 1.0000
18.8000 248.0000 1.0000
18.8600 278.0000 1.0000
18.9200 251.0000 1.0000
18.9800 242.0000 1.0000
19.0400 244.0000 1.0000
19.1000 248.0000 1.0000
19.1600 257.0000 1.0000
19.2200 263.0000 1.0000
19.2800 270.0000 1.0000
19.3400 254.0000 1.0000
19.4000 258.0000 1.0000
19.4600 245.0000 1.0000
19.5200 251.0000 1.0000
19.5800 245.0000 1.0000
19.6400 255.0000 1.0000
19.7000 244.0000 1.0000
19.7600 242.0000 1.0000
19.8200 246.0000 1.0000
19.8800 248.0000 1.0000
19.9400 258.0000 1.0000
20.0000 246.0000 1.0000
20.0600 227.0000 1.0000
20.1200 247.0000 1.0000
20.1800 224.0000 1.0000
20.2400 243.0000 1.0000
20.3000 233.0000 1.0000
20.3600 232.0000 1.0000
20.4200 241.0000 1.0000
20.4800 233.0000 1.0000
20.5400 239.0000 1.0000
20.6000 233.0000 1.0000
20.6600 230.0000 1.0000
20.7200 228.0000 1.0000
20.7800 236.0000 1.0000
20.8400 223.0000 1.0000
20.9000 233.0000 1.0000
20.9600 227.0000 1.0000
21.0200 227.0000 1.0000
21.0800 220.0000 1.0000
21.1400 219.0000 1.0000
21.2000 208.0000 1.0000
21.2600 219.0000 1.0000
21.3200 216.0000 1.0000
21.3800 203.0000 1.0000
21.4400 217.0000 1.0000
21.5000 204.0000 1.0000
21.5600 210.0000 1.0000
21.6200 227.0000 1.0000
21.6800 227.0000 1.0000
21.7400 209.0000 1.0000
21.8000 219.0000 1.0000
21.8600 217.0000 1.0000
21.9200 229.0000 1.0000
21.9800 211.0000 1.0000
22.0400 210.0000 1.0000
22.1000 208.0000 1.0000
22.1600 222.0000 1.0000
22.2200 194.0000 1.0000
22.2800 203.0000 1.0000
22.3400 194.0000 1.0000
22.4000 207.0000 1.0000
22.4600 209.0000 1.0000
22.5200 187.0000 1.0000
22.5800 185.0000 1.0000
22.6400 208.0000 1.0000
22.7000 187.0000 1.0000
22.7600 208.0000 1.0000
22.8200 179.0000 1.0000
22.8800 211.0000 1.0000
22.9400 191.0000 1.0000
23.0000 196.0000 1.0000
23.0600 182.0000 1.0000
23.1200 190.0000 1.0000
23.1800 183.0000 1.0000
23.2400 202.0000 1.0000
23.3000 182.0000 1.0000
23.3600 208.0000 1.0000
23.4200 191.0000 1.0000
23.4800 188.0000 1.0000
23.5400 185.0000 1.0000
23.6000 174.0000 1.0000
23.6600 206.0000 1.0000
23.7200 197.0000 1.0000
23.7800 187.0000 1.0000
23.8400 181.0000 1.0000
23.9000 182.0000 1.0000
23.9600 179.0000 1.0000
24.0200 188.0000 1.0000
24.0800 181.0000 1.0000
24.1400 186.0000 1.0000
24.2000 175.0000 1.0000
24.2600 185.0000 1.0000
24.3200 186.0000 1.0000
24.3800 179.0000 1.0000
24.4400 173.0000 1.0000
24.5000 163.0000 1.0000
24.5600 168.0000 1.0000
24.6200 183.0000 1.0000
24.6800 179.0000 1.0000
24.7400 180.0000 1.0000
24.8000 157.0000 1.0000
24.8600 172.0000 1.0000
24.9200 172.0000 1.0000
24.9800 167.0000 1.0000
25.0400 173.0000 1.0000
25.1000 167.0000 1.0000
25.1600 177.0000 1.0000
25.2200 161.0000 1.0000
25.2800 177.0000 1.0000
25.3400 170.0000 1.0000
25.4000 164.0000 1.0000
25.4600 166.0000 1.0000
25.5200 167.0000 1.0000
25.5800 160.0000 1.0000
25.6400 181.0000 1.0000
25.7000 165.0000 1.0000
25.7600 176.0000 1.0000
25.8200 176.0000 1.0000
25.8800 170.0000 1.0000
25.9400 156.0000 1.0000
26.0000 173.0000 1.0000
26.0600 165.0000 1.0000
26.1200 167.0000 1.0000
26.1800 155.0000 1.0000
26.2400 165.0000 1.0000
26.3000 161.0000 1.0000
26.3600 163.0000 1.0000
26.4200 152.0000 1.0000
26.4800 166.0000 1.0000
26.5400 152.0000 1.0000
26.6000 149.0000 1.0000
26.6600 163.0000 1.0000
26.7200 163.0000 1.0000
26.7800 164.0000 1.0000
26.8400 152.0000 1.0000
26.9000 156.0000 1.0000
26.9600 152.0000 1.0000
27.0200 153.0000 1.0000
27.0800 148.0000 1.0000
27.1400 158.0000 1.0000
27.2000 156.0000 1.0000
27.2600 148.0000 1.0000
27.3200 155.0000 1.0000
27.3800 155.0000 1.0000
27.4400 134.0000 1.0000
27.5000 165.0000 1.0000
27.5600 167.0000 1.0000
27.6200 165.0000 1.0000
27.6800 137.0000 1.0000
27.7400 156.0000 1.0000
27.8000 148.0000 1.0000
27.8600 142.0000 1.0000
27.9200 152.0000 1.0000
27.9800 153.0000 1.0000
28.0400 140.0000 1.0000
28.1000 164.0000 1.0000
28.1600 136.0000 1.0000
28.2200 152.0000 1.0000
28.2800 136.0000 1.0000
28.3400 140.0000 1.0000
28.4000 150.0000 1.0000
28.4600 144.0000 1.0000
28.5200 141.0000 1.0000
28.5800 142.0000 1.0000
28.6400 158.0000 1.0000
28.7000 150.0000 1.0000
28.7600 143.0000 1.0000
28.8200 136.0000 1.0000
28.8800 150.0000 1.0000
28.9400 140.0000 1.0000
29.0000 145.0000 1.0000
29.0600 136.0000 1.0000
29.1200 143.0000 1.0000
29.1800 145.0000 1.0000
29.2400 161.0000 1.0000
29.3000 141.0000 1.0000
29.3600 160.0000 1.0000
29.4200 158.0000 1.0000
29.4800 162.0000 1.0000
29.5400 173.0000 1.0000
29.6000 184.0000 1.0000
29.6600 196.0000 1.0000
29.7200 198.0000 1.0000
29.7800 207.0000 1.0000
29.8400 234.0000 1.0000
29.9000 310.0000 1.0000
29.9600 511.0000 1.0000
30.0200 846.0000 1.0000
30.0800 1185.0000 1.0000
30.1400 1066.0000 1.0000
30.2000 744.0000 1.0000
30.2600 513.0000 1.0000
30.3200 437.0000 1.0000
30.3800 488.0000 1.0000
30.4400 761.0000 1.0000
30.5000 1696.0000 1.0000
30.5600 3433.0000 1.0000
30.6200 3896.0000 1.0000
30.6800 2511.0000 1.0000
30.7400 1138.0000 1.0000
30.8000 521.0000 1.0000
30.8600 349.0000 1.0000
30.9200 280.0000 1.0000
30.9800 238.0000 1.0000
31.0400 203.0000 1.0000
31.1000 191.0000 1.0000
31.1600 178.0000 1.0000
31.2200 168.0000 1.0000
31.2800 158.0000 1.0000
31.3400 147.0000 1.0000
31.4000 178.0000 1.0000
31.4600 170.0000 1.0000
31.5200 164.0000 1.0000
31.5800 200.0000 1.0000
31.6400 192.0000 1.0000
31.7000 195.0000 1.0000
31.7600 244.0000 1.0000
31.8200 345.0000 1.0000
31.8800 730.0000 1.0000
31.9400 1615.0000 1.0000
32.0000 1686.0000 1.0000
32.0600 1145.0000 1.0000
32.1200 512.0000 1.0000
32.1800 251.0000 1.0000
32.2400 202.0000 1.0000
32.3000 180.0000 1.0000
32.3600 145.0000 1.0000
32.4200 159.0000 1.0000
32.4800 149.0000 1.0000
32.5400 131.0000 1.0000
32.6000 146.0000 1.0000
32.6600 140.0000 1.0000
32.7200 137.0000 1.0000
32.7800 134.0000 1.0000
32.8400 140.0000 1.0000
32.9000 130.0000 1.0000
32.9600 126.0000 1.0000
33.0200 131.0000 1.0000
33.0800 127.0000 1.0000
33.1400 119.0000 1.0000
33.2000 122.0000 1.0000
33.2600 117.0000 1.0000
33.3200 115.0000 1.0000
33.3800 122.0000 1.0000
33.4400 139.0000 1.0000
33.5000 121.0000 1.0000
33.5600 118.0000 1.0000
33.6200 122.0000 1.0000
33.6800 121.0000 1.0000
33.7400 121.0000 1.0000
33.8000 124.0000 1.0000
33.8600 135.0000 1.0000
33.9200 112.0000 1.0000
33.9800 120.0000 1.0000
34.0400 122.0000 1.0000
34.1000 123.0000 1.0000
34.1600 112.0000 1.0000
34.2200 114.0000 1.0000
34.2800 112.0000 1.0000
34.3400 123.0000 1.0000
34.4000 117.0000 1.0000
34.4600 118.0000 1.0000
34.5200 112.0000 1.0000
34.5800 115.0000 1.0000
34.6400 109.0000 1.0000
34.7000 130.0000 1.0000
34.7600 117.0000 1.0000
34.8200 112.0000 1.0000
34.8800 116.0000 1.0000
34.9400 115.0000 1.0000
35.0000 118.0000 1.0000
35.0600 122.0000 1.0000
35.1200 125.0000 1.0000
35.1800 143.0000 1.0000
35.2400 139.0000 1.0000
35.3000 112.0000 1.0000
35.3600 126.0000 1.0000
35.4200 110.0000 1.0000
35.4800 121.0000 1.0000
35.5400 109.0000 1.0000
35.6000 111.0000 1.0000
35.6600 102.0000 1.0000
35.7200 112.0000 1.0000
35.7800 106.0000 1.0000
35.8400 116.0000 1.0000
35.9000 114.0000 1.0000
35.9600 111.0000 1.0000
36.0200 103.0000 1.0000
36.0800 113.0000 1.0000
36.1400 110.0000 1.0000
36.2000 99.0000 1.0000
36.2600 100.0000 1.0000
36.3200 110.0000 1.0000
36.3800 104.0000 1.0000
36.4400 102.0000 1.0000
36.5000 103.0000 1.0000
36.5600 96.0000 1.0000
36.6200 112.0000 1.0000
36.6800 107.0000 1.0000
36.7400 105.0000 1.0000
36.8000 103.0000 1.0000
36.8600 96.0000 1.0000
36.9200 121.0000 1.0000
36.9800 102.0000 1.0000
37.0400 97.0000 1.0000
37.1000 100.0000 1.0000
37.1600 107.0000 1.0000
37.2200 111.0000 1.0000
37.2800 115.0000 1.0000
37.3400 103.0000 1.0000
37.4000 103.0000 1.0000
37.4600 107.0000 1.0000
37.5200 100.0000 1.0000
37.5800 103.0000 1.0000
37.6400 106.0000 1.0000
37.7000 97.0000 1.0000
37.7600 100.0000 1.0000
37.8200 100.0000 1.0000
37.8800 102.0000 1.0000
37.9400 100.0000 1.0000
38.0000 104.0000 1.0000
38.0600 115.0000 1.0000
38.1200 100.0000 1.0000
38.1800 106.0000 1.0000
38.2400 101.0000 1.0000
38.3000 94.0000 1.0000
38.3600 105.0000 1.0000
38.4200 106.0000 1.0000
38.4800 105.0000 1.0000
38.5400 106.0000 1.0000
38.6000 102.0000 1.0000
38.6600 103.0000 1.0000
38.7200 106.0000 1.0000
38.7800 109.0000 1.0000
38.8400 97.0000 1.0000
38.9000 94.0000 1.0000
38.9600 116.0000 1.0000
39.0200 104.0000 1.0000
39.0800 101.0000 1.0000
39.1400 95.0000 1.0000
39.2000 108.0000 1.0000
39.2600 102.0000 1.0000
39.3200 112.0000 1.0000
39.3800 104.0000 1.0000
39.4400 104.0000 1.0000
39.5000 111.0000 1.0000
39.5600 96.0000 1.0000
39.6200 96.0000 1.0000
39.6800 102.0000 1.0000
39.7400 104.0000 1.0000
39.8000 105.0000 1.0000
39.8600 96.0000 1.0000
39.9200 108.0000 1.0000
39.9800 97.0000 1.0000
40.0400 86.0000 1.0000
40.1000 90.0000 1.0000
40.1600 101.0000 1.0000
40.2200 99.0000 1.0000
40.2800 94.0000 1.0000
40.3400 105.0000 1.0000
40.4000 91.0000 1.0000
40.4600 103.0000 1.0000
40.5200 82.0000 1.0000
40.5800 113.0000 1.0000
40.6400 94.0000 1.0000
40.7000 99.0000 1.0000
40.7600 111.0000 1.0000
40.8200 98.0000 1.0000
40.8800 84.0000 1.0000
40.9400 91.0000 1.0000
41.0000 91.0000 1.0000
41.0600 96.0000 1.0000
41.1200 109.0000 1.0000
41.1800 112.0000 1.0000
41.2400 104.0000 1.0000
41.3000 93.0000 1.0000
41.3600 88.0000 1.0000
41.4200 106.0000 1.0000
41.4800 96.0000 1.0000
41.5400 97.0000 1.0000
41.6000 106.0000 1.0000
41.6600 102.0000 1.0000
41.7200 106.0000 1.0000
41.7800 104.0000 1.0000
41.8400 93.0000 1.0000
41.9000 104.0000 1.0000
41.9600 106.0000 1.0000
42.0200 106.0000 1.0000
42.0800 94.0000 1.0000
42.1400 102.0000 1.0000
42.2000 111.0000 1.0000
42.2600 108.0000 1.0000
42.3200 110.0000 1.0000
42.3800 110.0000 1.0000
42.4400 119.0000 1.0000
42.5000 129.0000 1.0000
42.5600 136.0000 1.0000
42.6200 138.0000 1.0000
42.6800 203.0000 1.0000
42.7400 258.0000 1.0000
42.8000 385.0000 1.0000
42.8600 599.0000 1.0000
42.9200 748.0000 1.0000
42.9800 731.0000 1.0000
43.0400 610.0000 1.0000
43.1000 483.0000 1.0000
43.1600 456.0000 1.0000
43.2200 486.0000 1.0000
43.2800 522.0000 1.0000
43.3400 472.0000 1.0000
43.4000 355.0000 1.0000
43.4600 259.0000 1.0000
43.5200 176.0000 1.0000
43.5800 172.0000 1.0000
43.6400 143.0000 1.0000
43.7000 178.0000 1.0000
43.7600 262.0000 1.0000
43.8200 469.0000 1.0000
43.8800 397.0000 1.0000
43.9400 338.0000 1.0000
44.0000 248.0000 1.0000
44.0600 149.0000 1.0000
44.1200 123.0000 1.0000
44.1800 123.0000 1.0000
44.2400 121.0000 1.0000
44.3000 106.0000 1.0000
44.3600 111.0000 1.0000
44.4200 118.0000 1.0000
44.4800 104.0000 1.0000
44.5400 128.0000 1.0000
44.6000 141.0000 1.0000
44.6600 170.0000 1.0000
44.7200 218.0000 1.0000
44.7800 442.0000 1.0000
44.8400 885.0000 1.0000
44.9000 836.0000 1.0000
44.9600 653.0000 1.0000
45.0200 433.0000 1.0000
45.0800 203.0000 1.0000
45.1400 139.0000 1.0000
45.2000 119.0000 1.0000
45.2600 111.0000 1.0000
45.3200 111.0000 1.0000
45.3800 103.0000 1.0000
45.4400 109.0000 1.0000
45.5000 104.0000 1.0000
45.5600 96.0000 1.0000
45.6200 104.0000 1.0000
45.6800 93.0000 1.0000
45.7400 96.0000 1.0000
45.8000 84.0000 1.0000
45.8600 87.0000 1.0000
45.9200 100.0000 1.0000
45.9800 91.0000 1.0000
46.0400 93.0000 1.0000
46.1000 88.0000 1.0000
46.1600 104.0000 1.0000
46.2200 91.0000 1.0000
46.2800 89.0000 1.0000
46.3400 99.0000 1.0000
46.4000 94.0000 1.0000
46.4600 93.0000 1.0000
46.5200 88.0000 1.0000
46.5800 95.0000 1.0000
46.6400 97.0000 1.0000
46.7000 99.0000 1.0000
46.7600 96.0000 1.0000
46.8200 93.0000 1.0000
46.8800 97.0000 1.0000
46.9400 88.0000 1.0000
47.0000 85.0000 1.0000
47.0600 86.0000 1.0000
47.1200 95.0000 1.0000
47.1800 90.0000 1.0000
47.2400 82.0000 1.0000
47.3000 89.0000 1.0000
47.3600 86.0000 1.0000
47.4200 87.0000 1.0000
47.4800 94.0000 1.0000
47.5400 90.0000 1.0000
47.6000 97.0000 1.0000
47.6600 80.0000 1.0000
47.7200 92.0000 1.0000
47.7800 89.0000 1.0000
47.8400 80.0000 1.0000
47.9000 87.0000 1.0000
47.9600 98.0000 1.0000
48.0200 93.0000 1.0000
48.0800 87.0000 1.0000
48.1400 82.0000 1.0000
48.2000 93.0000 1.0000
48.2600 81.0000 1.0000
48.3200 90.0000 1.0000
48.3800 86.0000 1.0000
48.4400 96.0000 1.0000
48.5000 95.0000 1.0000
48.5600 82.0000 1.0000
48.6200 83.0000 1.0000
48.6800 82.0000 1.0000
48.7400 92.0000 1.0000
48.8000 94.0000 1.0000
48.8600 91.0000 1.0000
48.9200 86.0000 1.0000
48.9800 79.0000 1.0000
49.0400 90.0000 1.0000
49.1000 86.0000 1.0000
49.1600 99.0000 1.0000
49.2200 93.0000 1.0000
49.2800 96.0000 1.0000
49.3400 88.0000 1.0000
49.4000 83.0000 1.0000
49.4600 92.0000 1.0000
49.5200 96.0000 1.0000
49.5800 97.0000 1.0000
49.6400 79.0000 1.0000
49.7000 95.0000 1.0000
49.7600 81.0000 1.0000
49.8200 95.0000 1.0000
49.8800 92.0000 1.0000
49.9400 93.0000 1.0000
50.0000 103.0000 1.0000
50.0600 88.0000 1.0000
50.1200 96.0000 1.0000
50.1800 84.0000 1.0000
50.2400 94.0000 1.0000
50.3000 90.0000 1.0000
50.3600 89.0000 1.0000
50.4200 83.0000 1.0000
50.4800 92.0000 1.0000
50.5400 84.0000 1.0000
50.6000 89.0000 1.0000
50.6600 81.0000 1.0000
50.7200 86.0000 1.0000
50.7800 92.0000 1.0000
50.8400 89.0000 1.0000
50.9000 89.0000 1.0000
50.9600 96.0000 1.0000
51.0200 94.0000 1.0000
51.0800 83.0000 1.0000
51.1400 72.0000 1.0000
51.2000 82.0000 1.0000
51.2600 76.0000 1.0000
51.3200 74.0000 1.0000
51.3800 89.0000 1.0000
51.4400 101.0000 1.0000
51.5000 86.0000 1.0000
51.5600 85.0000 1.0000
51.6200 74.0000 1.0000
51.6800 103.0000 1.0000
51.7400 83.0000 1.0000
51.8000 92.0000 1.0000
51.8600 86.0000 1.0000
51.9200 100.0000 1.0000
51.9800 93.0000 1.0000
52.0400 81.0000 1.0000
52.1000 85.0000 1.0000
52.1600 78.0000 1.0000
52.2200 95.0000 1.0000
52.2800 87.0000 1.0000
52.3400 89.0000 1.0000
52.4000 85.0000 1.0000
52.4600 85.0000 1.0000
52.5200 74.0000 1.0000
52.5800 88.0000 1.0000
52.6400 84.0000 1.0000
52.7000 105.0000 1.0000
52.7600 97.0000 1.0000
52.8200 88.0000 1.0000
52.8800 96.0000 1.0000
52.9400 90.0000 1.0000
53.0000 105.0000 1.0000
53.0600 116.0000 1.0000
53.1200 117.0000 1.0000
53.1800 132.0000 1.0000
53.2400 159.0000 1.0000
53.3000 205.0000 1.0000
53.3600 212.0000 1.0000
53.4200 206.0000 1.0000
53.4800 189.0000 1.0000
53.5400 162.0000 1.0000
53.6000 125.0000 1.0000
53.6600 105.0000 1.0000
53.7200 111.0000 1.0000
53.7800 97.0000 1.0000
53.8400 86.0000 1.0000
53.9000 98.0000 1.0000
53.9600 87.0000 1.0000
54.0200 95.0000 1.0000
54.0800 81.0000 1.0000
54.1400 99.0000 1.0000
54.2000 86.0000 1.0000
54.2600 83.0000 1.0000
54.3200 93.0000 1.0000
54.3800 77.0000 1.0000
54.4400 94.0000 1.0000
54.5000 90.0000 1.0000
54.5600 90.0000 1.0000
54.6200 89.0000 1.0000
54.6800 85.0000 1.0000
54.7400 100.0000 1.0000
54.8000 101.0000 1.0000
54.8600 108.0000 1.0000
54.9200 110.0000 1.0000
54.9800 108.0000 1.0000
55.0400 122.0000 1.0000
55.1000 133.0000 1.0000
55.1600 158.0000 1.0000
55.2200 288.0000 1.0000
55.2800 445.0000 1.0000
55.3400 456.0000 1.0000
55.4000 356.0000 1.0000
55.4600 322.0000 1.0000
55.5200 215.0000 1.0000
55.5800 179.0000 1.0000
55.6400 137.0000 1.0000
55.7000 118.0000 1.0000
55.7600 120.0000 1.0000
55.8200 94.0000 1.0000
55.8800 94.0000 1.0000
55.9400 97.0000 1.0000
56.0000 94.0000 1.0000
56.0600 92.0000 1.0000
56.1200 98.0000 1.0000
56.1800 97.0000 1.0000
56.2400 112.0000 1.0000
56.3000 112.0000 1.0000
56.3600 112.0000 1.0000
56.4200 103.0000 1.0000
56.4800 100.0000 1.0000
56.5400 111.0000 1.0000
56.6000 126.0000 1.0000
56.6600 134.0000 1.0000
56.7200 135.0000 1.0000
56.7800 132.0000 1.0000
56.8400 115.0000 1.0000
56.9000 98.0000 1.0000
56.9600 99.0000 1.0000
57.0200 103.0000 1.0000
57.0800 99.0000 1.0000
57.1400 107.0000 1.0000
57.2000 101.0000 1.0000
57.2600 99.0000 1.0000
57.3200 107.0000 1.0000
57.3800 99.0000 1.0000
57.4400 102.0000 1.0000
57.5000 99.0000 1.0000
57.5600 101.0000 1.0000
57.6200 89.0000 1.0000
57.6800 101.0000 1.0000
57.7400 89.0000 1.0000
57.8000 98.0000 1.0000
57.8600 98.0000 1.0000
57.9200 96.0000 1.0000
57.9800 98.0000 1.0000
58.0400 115.0000 1.0000
58.1000 94.0000 1.0000
58.1600 103.0000 1.0000
58.2200 101.0000 1.0000
58.2800 96.0000 1.0000
58.3400 93.0000 1.0000
58.4000 100.0000 1.0000
58.4600 94.0000 1.0000
58.5200 110.0000 1.0000
58.5800 98.0000 1.0000
58.6400 95.0000 1.0000
58.7000 117.0000 1.0000
58.7600 96.0000 1.0000
58.8200 100.0000 1.0000
58.8800 97.0000 1.0000
58.9400 103.0000 1.0000
59.0000 92.0000 1.0000
59.0600 100.0000 1.0000
59.1200 99.0000 1.0000
59.1800 103.0000 1.0000
59.2400 86.0000 1.0000
59.3000 98.0000 1.0000
59.3600 99.0000 1.0000
59.4200 87.0000 1.0000
59.4800 99.0000 1.0000
59.5400 92.0000 1.0000
59.6000 105.0000 1.0000
59.6600 106.0000 1.0000
59.7200 87.0000 1.0000
59.7800 98.0000 1.0000
59.8400 118.0000 1.0000
59.9000 127.0000 1.0000
59.9600 144.0000 1.0000
60.0200 145.0000 1.0000
60.0800 151.0000 1.0000
60.1400 139.0000 1.0000
60.2000 130.0000 1.0000
60.2600 121.0000 1.0000
60.3200 121.0000 1.0000
60.3800 109.0000 1.0000
60.4400 108.0000 1.0000
60.5000 96.0000 1.0000
60.5600 104.0000 1.0000
60.6200 96.0000 1.0000
60.6800 91.0000 1.0000
60.7400 99.0000 1.0000
60.8000 105.0000 1.0000
60.8600 96.0000 1.0000
60.9200 95.0000 1.0000
60.9800 103.0000 1.0000
61.0400 112.0000 1.0000
61.1000 112.0000 1.0000
61.1600 90.0000 1.0000
61.2200 104.0000 1.0000
61.2800 98.0000 1.0000
61.3400 113.0000 1.0000
61.4000 100.0000 1.0000
61.4600 104.0000 1.0000
61.5200 95.0000 1.0000
61.5800 108.0000 1.0000
61.6400 106.0000 1.0000
61.7000 99.0000 1.0000
61.7600 106.0000 1.0000
61.8200 106.0000 1.0000
61.8800 105.0000 1.0000
61.9400 112.0000 1.0000
62.0000 120.0000 1.0000
62.0600 113.0000 1.0000
62.1200 125.0000 1.0000
62.1800 133.0000 1.0000
62.2400 143.0000 1.0000
62.3000 152.0000 1.0000
62.3600 219.0000 1.0000
62.4200 410.0000 1.0000
62.4800 716.0000 1.0000
62.5400 596.0000 1.0000
62.6000 518.0000 1.0000
62.6600 576.0000 1.0000
62.7200 424.0000 1.0000
62.7800 286.0000 1.0000
62.8400 224.0000 1.0000
62.9000 186.0000 1.0000
62.9600 151.0000 1.0000
63.0200 140.0000 1.0000
63.0800 122.0000 1.0000
63.1400 127.0000 1.0000
63.2000 118.0000 1.0000
63.2600 125.0000 1.0000
63.3200 118.0000 1.0000
63.3800 127.0000 1.0000
63.4400 153.0000 1.0000
63.5000 162.0000 1.0000
63.5600 193.0000 1.0000
63.6200 259.0000 1.0000
63.6800 418.0000 1.0000
63.7400 588.0000 1.0000
63.8000 560.0000 1.0000
63.8600 456.0000 1.0000
63.9200 391.0000 1.0000
63.9800 314.0000 1.0000
64.0400 252.0000 1.0000
64.1000 166.0000 1.0000
64.1600 157.0000 1.0000
64.2200 144.0000 1.0000
64.2800 129.0000 1.0000
64.3400 141.0000 1.0000
64.4000 143.0000 1.0000
64.4600 211.0000 1.0000
64.5200 303.0000 1.0000
64.5800 353.0000 1.0000
64.6400 232.0000 1.0000
64.7000 246.0000 1.0000
64.7600 239.0000 1.0000
64.8200 160.0000 1.0000
64.8800 138.0000 1.0000
64.9400 133.0000 1.0000
65.0000 116.0000 1.0000
65.0600 100.0000 1.0000
65.1200 102.0000 1.0000
65.1800 91.0000 1.0000
65.2400 104.0000 1.0000
65.3000 101.0000 1.0000
65.3600 105.0000 1.0000
65.4200 119.0000 1.0000
65.4800 105.0000 1.0000
65.5400 94.0000 1.0000
65.6000 95.0000 1.0000
65.6600 103.0000 1.0000
65.7200 112.0000 1.0000
65.7800 112.0000 1.0000
65.8400 95.0000 1.0000
65.9000 88.0000 1.0000
65.9600 110.0000 1.0000
66.0200 98.0000 1.0000
66.0800 99.0000 1.0000
66.1400 107.0000 1.0000
66.2000 104.0000 1.0000
66.2600 91.0000 1.0000
66.3200 98.0000 1.0000
66.3800 102.0000 1.0000
66.4400 101.0000 1.0000
66.5000 103.0000 1.0000
66.5600 98.0000 1.0000
66.6200 98.0000 1.0000
66.6800 90.0000 1.0000
66.7400 101.0000 1.0000
66.8000 114.0000 1.0000
66.8600 104.0000 1.0000
66.9200 107.0000 1.0000
66.9800 85.0000 1.0000
67.0400 96.0000 1.0000
67.1000 101.0000 1.0000
67.1600 96.0000 1.0000
67.2200 97.0000 1.0000
67.2800 98.0000 1.0000
67.3400 98.0000 1.0000
67.4000 90.0000 1.0000
67.4600 116.0000 1.0000
67.5200 89.0000 1.0000
67.5800 97.0000 1.0000
67.6400 94.0000 1.0000
67.7000 104.0000 1.0000
67.7600 94.0000 1.0000
67.8200 101.0000 1.0000
67.8800 92.0000 1.0000
67.9400 102.0000 1.0000
68.0000 89.0000 1.0000
68.0600 106.0000 1.0000
68.1200 111.0000 1.0000
68.1800 104.0000 1.0000
68.2400 101.0000 1.0000
68.3000 101.0000 1.0000
68.3600 92.0000 1.0000
68.4200 99.0000 1.0000
68.4800 108.0000 1.0000
68.5400 108.0000 1.0000
68.6000 104.0000 1.0000
68.6600 107.0000 1.0000
68.7200 99.0000 1.0000
68.7800 93.0000 1.0000
68.8400 92.0000 1.0000
68.9000 95.0000 1.0000
68.9600 86.0000 1.0000
69.0200 98.0000 1.0000
69.0800 98.0000 1.0000
69.1400 101.0000 1.0000
69.2000 103.0000 1.0000
69.2600 96.0000 1.0000
69.3200 97.0000 1.0000
69.3800 96.0000 1.0000
69.4400 100.0000 1.0000
69.5000 100.0000 1.0000
69.5600 102.0000 1.0000
69.6200 97.0000 1.0000
69.6800 97.0000 1.0000
69.7400 107.0000 1.0000
69.8000 105.0000 1.0000
69.8600 105.0000 1.0000
69.9200 101.0000 1.0000
69.9800 93.0000 1.0000
70.0400 118.0000 1.0000
70.1000 103.0000 1.0000
70.1600 103.0000 1.0000
70.2200 96.0000 1.0000
70.2800 109.0000 1.0000
70.3400 105.0000 1.0000
70.4000 116.0000 1.0000
70.4600 107.0000 1.0000
70.5200 118.0000 1.0000
70.5800 127.0000 1.0000
70.6400 139.0000 1.0000
70.7000 147.0000 1.0000
70.7600 162.0000 1.0000
70.8200 184.0000 1.0000
70.8800 178.0000 1.0000
70.9400 165.0000 1.0000
71.0000 159.0000 1.0000
71.0600 168.0000 1.0000
71.1200 133.0000 1.0000
71.1800 119.0000 1.0000
71.2400 116.0000 1.0000
71.3000 112.0000 1.0000
71.3600 93.0000 1.0000
71.4200 103.0000 1.0000
71.4800 107.0000 1.0000
71.5400 96.0000 1.0000
71.6000 103.0000 1.0000
71.6600 106.0000 1.0000
71.7200 94.0000 1.0000
71.7800 92.0000 1.0000
71.8400 96.0000 1.0000
71.9000 97.0000 1.0000
71.9600 116.0000 1.0000
72.0200 105.0000 1.0000
72.0800 109.0000 1.0000
72.1400 112.0000 1.0000
72.2000 125.0000 1.0000
72.2600 152.0000 1.0000
72.3200 203.0000 1.0000
72.3800 260.0000 1.0000
72.4400 222.0000 1.0000
72.5000 189.0000 1.0000
72.5600 190.0000 1.0000
72.6200 187.0000 1.0000
72.6800 139.0000 1.0000
72.7400 128.0000 1.0000
72.8000 118.0000 1.0000
72.8600 124.0000 1.0000
72.9200 116.0000 1.0000
72.9800 143.0000 1.0000
73.0400 208.0000 1.0000
73.1000 237.0000 1.0000
73.1600 250.0000 1.0000
73.2200 213.0000 1.0000
73.2800 195.0000 1.0000
73.3400 193.0000 1.0000
73.4000 172.0000 1.0000
73.4600 130.0000 1.0000
73.5200 118.0000 1.0000
73.5800 118.0000 1.0000
73.6400 112.0000 1.0000
73.7000 95.0000 1.0000
73.7600 107.0000 1.0000
73.8200 98.0000 1.0000
73.8800 95.0000 1.0000
73.9400 85.0000 1.0000
74.0000 103.0000 1.0000
74.0600 90.0000 1.0000
74.1200 103.0000 1.0000
74.1800 94.0000 1.0000
74.2400 104.0000 1.0000
74.3000 105.0000 1.0000
74.3600 113.0000 1.0000
74.4200 99.0000 1.0000
74.4800 106.0000 1.0000
74.5400 116.0000 1.0000
74.6000 104.0000 1.0000
74.6600 86.0000 1.0000
74.7200 80.0000 1.0000
74.7800 98.0000 1.0000
74.8400 87.0000 1.0000
74.9000 89.0000 1.0000
74.9600 95.0000 1.0000
75.0200 89.0000 1.0000
75.0800 93.0000 1.0000
75.1400 103.0000 1.0000
75.2000 96.0000 1.0000
75.2600 91.0000 1.0000
75.3200 90.0000 1.0000
75.3800 99.0000 1.0000
75.4400 106.0000 1.0000
75.5000 103.0000 1.0000
75.5600 90.0000 1.0000
75.6200 89.0000 1.0000
75.6800 90.0000 1.0000
75.7400 103.0000 1.0000
75.8000 97.0000 1.0000
75.8600 94.0000 1.0000
75.9200 94.0000 1.0000
75.9800 99.0000 1.0000
76.0400 97.0000 1.0000
76.1000 87.0000 1.0000
76.1600 102.0000 1.0000
76.2200 92.0000 1.0000
76.2800 100.0000 1.0000
76.3400 90.0000 1.0000
76.4000 108.0000 1.0000
76.4600 112.0000 1.0000
76.5200 116.0000 1.0000
76.5800 110.0000 1.0000
76.6400 119.0000 1.0000
76.7000 102.0000 1.0000
76.7600 108.0000 1.0000
76.8200 118.0000 1.0000
76.8800 108.0000 1.0000
76.9400 100.0000 1.0000
77.0000 100.0000 1.0000
77.0600 102.0000 1.0000
77.1200 97.0000 1.0000
77.1800 100.0000 1.0000
77.2400 92.0000 1.0000
77.3000 87.0000 1.0000
77.3600 95.0000 1.0000
77.4200 103.0000 1.0000
77.4800 93.0000 1.0000
77.5400 104.0000 1.0000
77.6000 91.0000 1.0000
77.6600 93.0000 1.0000
77.7200 84.0000 1.0000
77.7800 90.0000 1.0000
77.8400 94.0000 1.0000
77.9000 101.0000 1.0000
77.9600 98.0000 1.0000
78.0200 80.0000 1.0000
78.0800 91.0000 1.0000
78.1400 92.0000 1.0000
78.2000 99.0000 1.0000
78.2600 100.0000 1.0000
78.3200 102.0000 1.0000
78.3800 113.0000 1.0000
78.4400 125.0000 1.0000
78.5000 136.0000 1.0000
78.5600 152.0000 1.0000
78.6200 159.0000 1.0000
78.6800 181.0000 1.0000
78.7400 181.0000 1.0000
78.8000 193.0000 1.0000
78.8600 212.0000 1.0000
78.9200 230.0000 1.0000
78.9800 225.0000 1.0000
79.0400 205.0000 1.0000
79.1000 190.0000 1.0000
79.1600 182.0000 1.0000
79.2200 158.0000 1.0000
79.2800 190.0000 1.0000
79.3400 200.0000 1.0000
79.4000 283.0000 1.0000
79.4600 351.0000 1.0000
79.5200 293.0000 1.0000
79.5800 203.0000 1.0000
79.6400 188.0000 1.0000
79.7000 216.0000 1.0000
79.7600 180.0000 1.0000
79.8200 130.0000 1.0000
79.8800 134.0000 1.0000
79.9400 98.0000 1.0000
80.0000 88.0000 1.0000
80.0600 87.0000 1.0000
80.1200 88.0000 1.0000
80.1800 85.0000 1.0000
80.2400 94.0000 1.0000
80.3000 85.0000 1.0000
80.3600 86.0000 1.0000
80.4200 78.0000 1.0000
80.4800 95.0000 1.0000
80.5400 88.0000 1.0000
80.6000 92.0000 1.0000
80.6600 95.0000 1.0000
80.7200 91.0000 1.0000
80.7800 88.0000 1.0000
80.8400 95.0000 1.0000
80.9000 87.0000 1.0000
80.9600 89.0000 1.0000
81.0200 99.0000 1.0000
81.0800 85.0000 1.0000
81.1400 85.0000 1.0000
81.2000 87.0000 1.0000
81.2600 91.0000 1.0000
81.3200 87.0000 1.0000
81.3800 85.0000 1.0000
81.4400 97.0000 1.0000
81.5000 78.0000 1.0000
81.5600 88.0000 1.0000
81.6200 85.0000 1.0000
81.6800 87.0000 1.0000
81.7400 89.0000 1.0000
81.8000 91.0000 1.0000
81.8600 92.0000 1.0000
81.9200 79.0000 1.0000
81.9800 89.0000 1.0000
82.0400 84.0000 1.0000
82.1000 80.0000 1.0000
82.1600 81.0000 1.0000
82.2200 80.0000 1.0000
82.2800 94.0000 1.0000
82.3400 81.0000 1.0000
82.4000 86.0000 1.0000
82.4600 89.0000 1.0000
82.5200 85.0000 1.0000
82.5800 76.0000 1.0000
82.6400 103.0000 1.0000
82.7000 85.0000 1.0000
82.7600 90.0000 1.0000
82.8200 90.0000 1.0000
82.8800 86.0000 1.0000
82.9400 89.0000 1.0000
83.0000 70.0000 1.0000
83.0600 80.0000 1.0000
83.1200 70.0000 1.0000
83.1800 98.0000 1.0000
83.2400 85.0000 1.0000
83.3000 79.0000 1.0000
83.3600 94.0000 1.0000
83.4200 90.0000 1.0000
83.4800 76.0000 1.0000
83.5400 99.0000 1.0000
83.6000 79.0000 1.0000
83.6600 72.0000 1.0000
83.7200 91.0000 1.0000
83.7800 78.0000 1.0000
83.8400 88.0000 1.0000
83.9000 87.0000 1.0000
83.9600 89.0000 1.0000
84.0200 88.0000 1.0000
84.0800 77.0000 1.0000
84.1400 72.0000 1.0000
84.2000 89.0000 1.0000
84.2600 87.0000 1.0000
84.3200 92.0000 1.0000
84.3800 73.0000 1.0000
84.4400 89.0000 1.0000
84.5000 83.0000 1.0000
84.5600 83.0000 1.0000
84.6200 86.0000 1.0000
84.6800 80.0000 1.0000
84.7400 74.0000 1.0000
84.8000 88.0000 1.0000
84.8600 81.0000 1.0000
84.9200 88.0000 1.0000
84.9800 65.0000 1.0000
85.0400 92.0000 1.0000
85.1000 86.0000 1.0000
85.1600 96.0000 1.0000
85.2200 82.0000 1.0000
85.2800 77.0000 1.0000
85.3400 80.0000 1.0000
85.4000 78.0000 1.0000
85.4600 69.0000 1.0000
85.5200 82.0000 1.0000
85.5800 74.0000 1.0000
85.6400 95.0000 1.0000
85.7000 79.0000 1.0000
85.7600 84.0000 1.0000
85.8200 88.0000 1.0000
85.8800 86.0000 1.0000
85.9400 72.0000 1.0000
86.0000 95.0000 1.0000
86.0600 81.0000 1.0000
86.1200 88.0000 1.0000
86.1800 88.0000 1.0000
86.2400 86.0000 1.0000
86.3000 86.0000 1.0000
86.3600 88.0000 1.0000
86.4200 90.0000 1.0000
86.4800 82.0000 1.0000
86.5400 88.0000 1.0000
86.6000 96.0000 1.0000
86.6600 93.0000 1.0000
86.7200 88.0000 1.0000
86.7800 86.0000 1.0000
86.8400 77.0000 1.0000
86.9000 89.0000 1.0000
86.9600 83.0000 1.0000
87.0200 94.0000 1.0000
87.0800 84.0000 1.0000
87.1400 83.0000 1.0000
87.2000 80.0000 1.0000
87.2600 93.0000 1.0000
87.3200 86.0000 1.0000
87.3800 87.0000 1.0000
87.4400 86.0000 1.0000
87.5000 89.0000 1.0000
87.5600 93.0000 1.0000
87.6200 89.0000 1.0000
87.6800 84.0000 1.0000
87.7400 88.0000 1.0000
87.8000 93.0000 1.0000
87.8600 88.0000 1.0000
87.9200 86.0000 1.0000
87.9800 90.0000 1.0000
88.0400 84.0000 1.0000
88.1000 83.0000 1.0000
88.1600 82.0000 1.0000
88.2200 83.0000 1.0000
88.2800 97.0000 1.0000
88.3400 69.0000 1.0000
88.4000 85.0000 1.0000
88.4600 88.0000 1.0000
88.5200 93.0000 1.0000
88.5800 93.0000 1.0000
88.6400 106.0000 1.0000
88.7000 84.0000 1.0000
88.7600 99.0000 1.0000
88.8200 92.0000 1.0000
88.8800 94.0000 1.0000
88.9400 106.0000 1.0000
89.0000 111.0000 1.0000
89.0600 108.0000 1.0000
89.1200 113.0000 1.0000
89.1800 121.0000 1.0000
89.2400 163.0000 1.0000
89.3000 187.0000 1.0000
89.3600 233.0000 1.0000
89.4200 212.0000 1.0000
89.4800 170.0000 1.0000
89.5400 162.0000 1.0000
89.6000 168.0000 1.0000
89.6600 189.0000 1.0000
89.7200 162.0000 1.0000
89.7800 150.0000 1.0000
89.8400 143.0000 1.0000
89.9000 143.0000 1.0000
89.9600 128.0000 1.0000
90.0000 137.0000 1.0000
*RAS_INT_END
*RAS_DATA_END